Workbook

Sheet 00_사용안내
B1: 재무제표분석과 기업가치평가 ─ 기업분석 포트폴리오 (Chapter 1 ~ 3) · 학생용
B2: 백복현·장궈화·최종학, 『재무제표분석과 기업가치평가』(박영사, 제4판) 1~3장 과제. 대상기업과 비교기업을 직접 고르고, DART 사업보고서와 주가자료로 노란 칸을 채워 나가세요. 금액 단위는 백만원, 주가는 원, 주식수는 천주로 통일합니다. 4장(현금흐름표) 이후 시트는 다음 시간에 배부합니다. 이 파일의 1~3장 입력이 이후 모든 분석의 기초가 되므로, 검증행에 OK가 뜨는지 반드시 확인하세요.
C4: ■ 셀 색상 규칙
C5: 표시 | D5: 의미
D6: 여러분이 직접 입력·조사해서 채우는 칸입니다.
C7: 파란색 글씨 + 연주황 배경 | D7: 여러분이 세우는 '가정' 값입니다. 이 칸을 바꾸면 결과가 함께 움직여야 합니다.
C8: 파란색 글씨 + 회색 배경 | D8: 작성 형식을 보여주는 예시 또는 주어진 자료입니다. 고치지 마세요.
C9: 검정색 글씨 | D9: 수식이 들어갈 칸입니다. 값을 직접 타이핑하면 안 됩니다.
C10: 빨간색 글씨 | D10: 검증용 칸입니다. 'OK'가 뜨는지 반드시 확인하세요.
C12: ■ 시트 구성 및 진행 순서
C13: 시트 | D13: 할 일
C14: 1-1_기업선정 | D14: [1장 과제①] 대상기업·비교기업을 고르고 DART 사업보고서에서 기본정보를 정리합니다.
C15: 1-2_기업개요비교 | D15: [1장 과제②] Chapter Report에 들어갈 산업·경쟁현황·제품·지배구조·경영자·감사인을 두 기업 나란히 비교합니다.
C16: 1-3_주가추이_월별 | D16: [1장 과제③] 최근 5년 60개월 월말 종가와 KOSPI로 수익률·지수화·그래프를 만들어 시장 대비 성과를 봅니다. (연도별 주가는 2-4 시트에 작성)
C17: 1-4_보고서비교 | D17: [1장 과제⑤] 증권사 애널리스트 보고서와 신용평가기관 보고서의 차이를 항목별로 대조합니다.
C18: 1-5_애널리스트보고서 | D18: 대상기업의 애널리스트 보고서(기준년도의 재무 데이터를 반영한 보고서)를 첨부·요약합니다.
C19: 1-6_신용평가보고서 | D19: 대상기업의 최근 신용평가 보고서(기준년도의 재무 데이터를 반영한 보고서)를 첨부·요약합니다.
C20: 2-0_왜_이_실습인가 | D20: [읽기] 2장 실습이 6·7·8·10·11장의 무엇에 쓰이는지 시트별 로드맵과 학기 지도. 각 항목에 강의노트 슬라이드 번호를 달았습니다.
C21: 2-1_재무상태표 | D21: [2장 과제①] 두 기업 6개년 재무상태표를 입력하고 오른쪽에 공통형 분석과 증감율(분석적 검토)을 작성합니다. 이후 모든 시트가 이 시트를 참조합니다.
C22: 2-2_공통형_해석 | D22: [2장 과제②] 공통형 분석 결과를 읽고 Chapter Report용 서술을 정리합니다.
C23: 2-3_PBR_비교 | D23: [2장 과제③] 기준년도 결산일 종가·유통주식수·지배기업 소유주지분으로 6개년 PBR을 계산·비교하고, 시가총액과 장부가치의 차이를 해석합니다.
C24: 3-1_손익계산서 | D24: [3장 과제①] 6개년 연결손익계산서를 입력하고 공통형(매출액 = 100%)·증감율을 계산합니다. PER·PBR을 함께 그린 그래프로 두 지표의 관계를 확인하고, Chapter Report 5개 항목을 서술합니다.
C25: 4-1 이후 | D25: 현금흐름표·수익성·위험·이익의 질·재무예측·기업가치평가(DCF·초과이익모형·상대가치) 시트는 다음 시간에 배부합니다.
C43: ■ 유의사항
C44: • | D44: 금액 단위는 백만원, 주가는 원, 주식수는 천주(2-3 시트)로 통일합니다. 사업보고서·DataGuide 원문 단위(원, 천원)와 다를 수 있으니 옮겨 적을 때 반드시 확인하세요.
C45: • | D45: 숫자를 손으로 계산해서 적지 마세요. 2-3·3-1 시트는 2-1 시트의 값에 수식으로 연결되어 있어, 원자료를 고치면 결과가 함께 바뀝니다.
C46: • | D46: 1-3 시트는 월별(60개월) 주가를, 2-3 시트는 연도별(결산일) 주가를 다룹니다. PBR은 결산일 장부가치와 짝을 맞춰야 하므로 연도별 주가를 씁니다.
C47: • | D47: 출처(사업보고서 페이지, URL, 조회일자)를 각 표의 '출처' 칸에 남겨두면 기말 보고서를 쓸 때 다시 찾는 수고를 덜 수 있습니다.
C48: • | D48: 시트 곳곳의 셀 메모(빨간 삼각형)에는 해당 개념이 강의노트 어느 장·어느 슬라이드에 나오는지 적어 두었습니다. "지금 이걸 왜 하는가"가 궁금하면 2-0 시트와 메모를 먼저 보세요.

Sheet 1-1_기업선정
B1: [과제 ①] 분석 대상기업 · 비교기업 선정
B2: DART(dart.fss.or.kr) 최근연도 사업보고서 → 'II. 사업의 개요'를 먼저 읽고 작성하세요.
C4: 항목 | D4: 대상기업 | E4: 비교기업 | F4: 확인 방법 / 메모
C5: 기업명 | F5: 사업보고서 표지
C6: 종목코드 | F6: 6자리. 예: 005930
C7: 상장시장 | F7: KOSPI / KOSDAQ / KONEX
C8: 상장일 | F8: 회사 개요 또는 KRX
C9: 업종 (표준산업분류) | F9: 사업보고서에 표준산업분류가 표기되어 있지 않습니다. DART 기업개황에서 확인해 채우세요.
C10: 주요 제품·서비스 | F10: 'II. 사업의 개요' 매출 구성
C11: 최근 사업연도 | F11: 예: 2025
C12: 시가총액 (백만원) | F12: 조회일 기준(stock.naver.com, DataGuide)
C13: 발행주식수 (주) | F13: 보통주 기준, 자기주식 포함. 메디톡스 자기주식 743,316주 · 휴젤 1,500,741주
C14: 최근 종가 (원) | F14: 조회일자 함께 기록
C15: 최대주주 및 지분율 | F15: '대주주 등에 관한 사항'
C16: 대표이사 | F16: '임원 및 직원 등에 관한 사항'
... C20: 자료 조회일자 | F20: YYYY-MM-DD
C22: 작성 예시 (참고용)
C23: 항목 | D23: 대상기업 | E23: 비교기업
C24: 기업명 | D24: 삼성생명 | E24: 한화생명
C25: 종목코드 | D25: 032830 | E25: 088350
C26: 상장시장 | D26: KOSPI | E26: KOSPI
C27: 업종 (표준산업분류) | D27: 보험업 (K65) | E27: 보험업 (K65)
C28: 시가총액 (백만원) | D28: 16,800,000 | E28: 2,700,000
C29: ※ 위 예시는 형식 안내용 숫자이며 실제 공시치가 아닙니다. 강의노트 1장의 삼성생명 사례에서 착안한 예시입니다.
C32: 비교기업 선정 사유 (3~5줄)

Sheet 1-2_기업개요비교
B1: [과제 ②] Chapter Report 작성용 기업개요 비교
B2: 본 장의 과제는 2장 분량의 Chapter Report입니다. 아래 항목이 보고서 목차가 됩니다. 여러분은 증권사 애널리스트입니다.
C4: 보고서 항목 | D4: 대상기업 | E4: 비교기업
C5: 산업 개요 및 시장규모
C6: 산업 내 경쟁현황 (주요 경쟁사·점유율)
C7: 주요 제조상품 / 서비스
C8: 매출 구성 (제품별·지역별 비중)
C9: 기업지배구조 (지분구조·이사회)
C10: 경영자 (대표이사 이력·경영전략)
C11: 회계감사인 및 감사의견
C12: 최근 3년 주요 이슈 (M&A, 소송, 규제 등)
C13: 투자포인트 (강점)
C14: 투자위험 (약점·리스크)
C17: 출처 기록
C18: 구분 | D18: 출처 (문서명 · 페이지 · URL) | E18: 조회일자
C19: 대상기업 사업보고서
C20: 비교기업 사업보고서
C21: 산업 통계·협회 자료
C22: 증권사 리포트
C23: 기타

Sheet 1-3_주가추이_월별
B1: [과제 ③] 월별 주가 변동추이와 시장대표지수(KOSPI) 비교 (60개월)
B2: 월말 종가 기준, 배당 미고려. 연도별(결산일) 주가와 PBR은 2-4 시트에서 다루므로 이 시트는 월별 흐름과 시장 대비 성과에 집중합니다.
C4: 작성 예시 (형식 참고용 · 지우지 마세요)
C5: 연월 | D5: 대상기업 종가(원) | E5: 비교기업 종가(원) | F5: KOSPI | G5: 대상 월수익률 | H5: 비교 월수익률 | I5: KOSPI 월수익률
C6: 2020-10 | D6: 60000 | E6: 25000 | F6: 2267 | G6: - | H6: - | I6: -
C7: 2020-11 | D7: 66700 | E7: 26500 | F7: 2591.3 | G7: =D7/D6-1 -> 0.11166667 | H7: =E7/E6-1 -> 0.06 | I7: =F7/F6-1 -> 0.14305249
C8: 2020-12 | D8: 81000 | E8: 27200 | F8: 2873.5 | G8: =D8/D7-1 -> 0.2143928 | H8: =E8/E7-1 -> 0.026415094 | I8: =F8/F7-1 -> 0.10890287
C9: ※ 월수익률 = 당월 종가 ÷ 전월 종가 − 1. 첫 행은 전월 자료가 없으므로 비워 둡니다.
C12: ■ 실습표 : 최근 5년(60개월) 월별 자료
C13: 연월 | D13: 대상기업 종가(원) | E13: 비교기업 종가(원) | F13: KOSPI | G13: 대상 월수익률 | H13: 비교 월수익률 | I13: KOSPI 월수익률 | J13: 대상 지수(100) | K13: 비교 지수(100) | L13: KOSPI 지수(100) | N13: ↑ 회색 아닌 흰 칸(월수익률·지수)은 비어 있습니다. 첫 3행의 수식을 확인한 뒤 60행까지 복사해 채우세요.
C14: 2021-01 | G14: - | H14: - | I14: - | J14: 100 | K14: 100 | L14: 100 | N14: 주가: DataGuide 일별종가 중 각 월 마지막 거래일 종가 사용 가능
C15: 2021-02 | G15: =IFERROR(D15/D14-1,"") | H15: =IFERROR(E15/E14-1,"") | I15: =IFERROR(F15/F14-1,"") | J15: =IFERROR(J14*(1+G15),"") | K15: =IFERROR(K14*(1+H15),"") | L15: =IFERROR(L14*(1+I15),"") | N15: 지수(100) = 전월 지수 × (1 + 당월 수익률). 시작 시점을 100으로 맞춰야 세 계열을 같은 출발선에서 비교할 수 있습니다.
C16: 2021-03 | G16: =IFERROR(D16/D15-1,"") | H16: =IFERROR(E16/E15-1,"") | I16: =IFERROR(F16/F15-1,"") | J16: =IFERROR(J15*(1+G16),"") | K16: =IFERROR(K15*(1+H16),"") | L16: =IFERROR(L15*(1+I16),"")
C17: 2021-04 | G17: =IFERROR(D17/D16-1,"") | H17: =IFERROR(E17/E16-1,"") | I17: =IFERROR(F17/F16-1,"") | J17: =IFERROR(J16*(1+G17),"") | K17: =IFERROR(K16*(1+H17),"") | L17: =IFERROR(L16*(1+I17),"")
C18: 2021-05 | G18: =IFERROR(D18/D17-1,"") | H18: =IFERROR(E18/E17-1,"") | I18: =IFERROR(F18/F17-1,"") | J18: =IFERROR(J17*(1+G18),"") | K18: =IFERROR(K17*(1+H18),"") | L18: =IFERROR(L17*(1+I18),"")
C19: 2021-06 | G19: =IFERROR(D19/D18-1,"") | H19: =IFERROR(E19/E18-1,"") | I19: =IFERROR(F19/F18-1,"") | J19: =IFERROR(J18*(1+G19),"") | K19: =IFERROR(K18*(1+H19),"") | L19: =IFERROR(L18*(1+I19),"")
C20: 2021-07 | G20: =IFERROR(D20/D19-1,"") | H20: =IFERROR(E20/E19-1,"") | I20: =IFERROR(F20/F19-1,"") | J20: =IFERROR(J19*(1+G20),"") | K20: =IFERROR(K19*(1+H20),"") | L20: =IFERROR(L19*(1+I20),"")
C21: 2021-08 | G21: =IFERROR(D21/D20-1,"") | H21: =IFERROR(E21/E20-1,"") | I21: =IFERROR(F21/F20-1,"") | J21: =IFERROR(J20*(1+G21),"") | K21: =IFERROR(K20*(1+H21),"") | L21: =IFERROR(L20*(1+I21),"")
C22: 2021-09 | G22: =IFERROR(D22/D21-1,"") | H22: =IFERROR(E22/E21-1,"") | I22: =IFERROR(F22/F21-1,"") | J22: =IFERROR(J21*(1+G22),"") | K22: =IFERROR(K21*(1+H22),"") | L22: =IFERROR(L21*(1+I22),"")
C23: 2021-10 | G23: =IFERROR(D23/D22-1,"") | H23: =IFERROR(E23/E22-1,"") | I23: =IFERROR(F23/F22-1,"") | J23: =IFERROR(J22*(1+G23),"") | K23: =IFERROR(K22*(1+H23),"") | L23: =IFERROR(L22*(1+I23),"")
C24: 2021-11 | G24: =IFERROR(D24/D23-1,"") | H24: =IFERROR(E24/E23-1,"") | I24: =IFERROR(F24/F23-1,"") | J24: =IFERROR(J23*(1+G24),"") | K24: =IFERROR(K23*(1+H24),"") | L24: =IFERROR(L23*(1+I24),"")
C25: 2021-12 | G25: =IFERROR(D25/D24-1,"") | H25: =IFERROR(E25/E24-1,"") | I25: =IFERROR(F25/F24-1,"") | J25: =IFERROR(J24*(1+G25),"") | K25: =IFERROR(K24*(1+H25),"") | L25: =IFERROR(L24*(1+I25),"")
C26: 2022-01 | G26: =IFERROR(D26/D25-1,"") | H26: =IFERROR(E26/E25-1,"") | I26: =IFERROR(F26/F25-1,"") | J26: =IFERROR(J25*(1+G26),"") | K26: =IFERROR(K25*(1+H26),"") | L26: =IFERROR(L25*(1+I26),"")
C27: 2022-02 | G27: =IFERROR(D27/D26-1,"") | H27: =IFERROR(E27/E26-1,"") | I27: =IFERROR(F27/F26-1,"") | J27: =IFERROR(J26*(1+G27),"") | K27: =IFERROR(K26*(1+H27),"") | L27: =IFERROR(L26*(1+I27),"")
... C33: 2022-08 | G33: =IFERROR(D33/D32-1,"") | H33: =IFERROR(E33/E32-1,"") | I33: =IFERROR(F33/F32-1,"") | J33: =IFERROR(J32*(1+G33),"") | K33: =IFERROR(K32*(1+H33),"") | L33: =IFERROR(L32*(1+I33),"")
C34: 2022-09 | G34: =IFERROR(D34/D33-1,"") | H34: =IFERROR(E34/E33-1,"") | I34: =IFERROR(F34/F33-1,"") | J34: =IFERROR(J33*(1+G34),"") | K34: =IFERROR(K33*(1+H34),"") | L34: =IFERROR(L33*(1+I34),"") | N34: 해석 (5줄 내외) : 대상기업 주가는 시장 대비 어떠했는가? 그 원인은?
C35: 2022-10 | G35: =IFERROR(D35/D34-1,"") | H35: =IFERROR(E35/E34-1,"") | I35: =IFERROR(F35/F34-1,"") | J35: =IFERROR(J34*(1+G35),"") | K35: =IFERROR(K34*(1+H35),"") | L35: =IFERROR(L34*(1+I35),"")
C36: 2022-11 | G36: =IFERROR(D36/D35-1,"") | H36: =IFERROR(E36/E35-1,"") | I36: =IFERROR(F36/F35-1,"") | J36: =IFERROR(J35*(1+G36),"") | K36: =IFERROR(K35*(1+H36),"") | L36: =IFERROR(L35*(1+I36),"")
C37: 2022-12 | G37: =IFERROR(D37/D36-1,"") | H37: =IFERROR(E37/E36-1,"") | I37: =IFERROR(F37/F36-1,"") | J37: =IFERROR(J36*(1+G37),"") | K37: =IFERROR(K36*(1+H37),"") | L37: =IFERROR(L36*(1+I37),"")
C38: 2023-01 | G38: =IFERROR(D38/D37-1,"") | H38: =IFERROR(E38/E37-1,"") | I38: =IFERROR(F38/F37-1,"") | J38: =IFERROR(J37*(1+G38),"") | K38: =IFERROR(K37*(1+H38),"") | L38: =IFERROR(L37*(1+I38),"")
C39: 2023-02 | G39: =IFERROR(D39/D38-1,"") | H39: =IFERROR(E39/E38-1,"") | I39: =IFERROR(F39/F38-1,"") | J39: =IFERROR(J38*(1+G39),"") | K39: =IFERROR(K38*(1+H39),"") | L39: =IFERROR(L38*(1+I39),"")
C40: 2023-03 | G40: =IFERROR(D40/D39-1,"") | H40: =IFERROR(E40/E39-1,"") | I40: =IFERROR(F40/F39-1,"") | J40: =IFERROR(J39*(1+G40),"") | K40: =IFERROR(K39*(1+H40),"") | L40: =IFERROR(L39*(1+I40),"")
C41: 2023-04 | G41: =IFERROR(D41/D40-1,"") | H41: =IFERROR(E41/E40-1,"") | I41: =IFERROR(F41/F40-1,"") | J41: =IFERROR(J40*(1+G41),"") | K41: =IFERROR(K40*(1+H41),"") | L41: =IFERROR(L40*(1+I41),"")
C42: 2023-05 | G42: =IFERROR(D42/D41-1,"") | H42: =IFERROR(E42/E41-1,"") | I42: =IFERROR(F42/F41-1,"") | J42: =IFERROR(J41*(1+G42),"") | K42: =IFERROR(K41*(1+H42),"") | L42: =IFERROR(L41*(1+I42),"")
C43: 2023-06 | G43: =IFERROR(D43/D42-1,"") | H43: =IFERROR(E43/E42-1,"") | I43: =IFERROR(F43/F42-1,"") | J43: =IFERROR(J42*(1+G43),"") | K43: =IFERROR(K42*(1+H43),"") | L43: =IFERROR(L42*(1+I43),"")
C44: 2023-07 | G44: =IFERROR(D44/D43-1,"") | H44: =IFERROR(E44/E43-1,"") | I44: =IFERROR(F44/F43-1,"") | J44: =IFERROR(J43*(1+G44),"") | K44: =IFERROR(K43*(1+H44),"") | L44: =IFERROR(L43*(1+I44),"")
C45: 2023-08 | G45: =IFERROR(D45/D44-1,"") | H45: =IFERROR(E45/E44-1,"") | I45: =IFERROR(F45/F44-1,"") | J45: =IFERROR(J44*(1+G45),"") | K45: =IFERROR(K44*(1+H45),"") | L45: =IFERROR(L44*(1+I45),"")
C46: 2023-09 | G46: =IFERROR(D46/D45-1,"") | H46: =IFERROR(E46/E45-1,"") | I46: =IFERROR(F46/F45-1,"") | J46: =IFERROR(J45*(1+G46),"") | K46: =IFERROR(K45*(1+H46),"") | L46: =IFERROR(L45*(1+I46),"")
... C73: 2025-12 | G73: =IFERROR(D73/D72-1,"") | H73: =IFERROR(E73/E72-1,"") | I73: =IFERROR(F73/F72-1,"") | J73: =IFERROR(J72*(1+G73),"") | K73: =IFERROR(K72*(1+H73),"") | L73: =IFERROR(L72*(1+I73),"")

Sheet 1-4_보고서비교
B1: [과제 ⑤] 증권사 애널리스트 보고서 vs 신용평가기관 보고서
B2: 한국신용평가 www.kisrating.com · 증권사 리포트는 각 사 홈페이지 또는 네이버 증권 리서치
C4: 비교 항목 | D4: 증권사 애널리스트 보고서 | E4: 신용평가기관 보고서
C5: 보고서 제목 · 발행기관 · 발행일
C6: 주된 이용자 (누구를 위해 쓰였는가)
C7: 분석의 초점 (수익성 / 상환능력)
C8: 결론의 형태 (투자의견·목표주가 / 신용등급)
C9: 예측 기간
C10: 중점적으로 본 재무지표
C11: 비재무정보 활용 정도
C12: 낙관/보수 정도에 대한 인상
C15: 왜 두 보고서의 결론이 다른가? (10줄 내외)

Sheet 1-5_애널리스트보고서
B1: 애널리스트 보고서 첨부 · 요약
B2: PDF 원문을 이 시트에 개체 삽입하거나 핵심 표(실적 추정·목표주가·P/B 밴드)를 옮겨 적으세요.

Sheet 1-6_신용평가보고서
B1: 신용평가 보고서 첨부 · 요약
B2: PDF 원문을 개체 삽입하거나 주요 재무지표·등급논리를 옮겨 적으세요.

Sheet 2-0_왜_이_실습인가
B1: 왜 이 실습을 하는가 — 실습이 11장 가치평가로 이어지는 길 (강의노트 슬라이드 참조)
B2: 가치평가 모형은 11장에서 배우지만, 지금 하는 재무상태표 분석이 그 모형의 "출발점"이 됩니다. 각 시트가 이후 어느 장의 무엇에 쓰이는지 미리 보여줍니다. [Chxx 슬라이드 n] 표기는 해당 장 강의노트의 슬라이드 번호입니다.
C4: ■ 이 과목의 한 줄 공식
C5: 가치 V₀ = Σ CFₜ ÷ (1 + r)ᵗ — 2장에서 처음 등장[Ch02 슬라이드 8]하고, 7장이 분모 r(할인율)을, 10장이 분자 CF(예측)를 만들며, 11장에서 둘을 결합합니다[Ch11 슬라이드 21]. 재무상태표는 이 공식의 출발점입니다: "재무상태표를 보고 가치를 평가하는 것은 기업가치평가의 출발점"[Ch02 슬라이드 7].
C7: ■ 시트별 로드맵: 지금 하는 일 → 나중에 쓰이는 곳 → 실무에서는
C8: 시트 | D8: 작업 | E8: 나중에 어디에 쓰이는가 (장·슬라이드) | F8: 가치평가에서의 역할 | G8: 실무적 적용
C9: 1-1 기업선정 1-2 기업개요비교 | D9: 대상·비교기업을 고르고 사업·지배구조·감사인을 정리한다. | E9: 3장 횡단면분석의 전제 "동종업계·유사 규모"[Ch03 슬라이드 18] · 5장 산업평균 비교의 함정(공상은행)[Ch05 슬라이드 15] · 11장 상대가치의 비교기업 선정 기준(자산·매출 규모, 산업, 부채비율, 발전단계)[Ch11 슬라이드 15 노트] | F9: 비교기업이 부적절하면 이후 모든 횡단면 비교(ROE 격차, PBR 배수)가 회계 차이인지 사업 차이인지 구분할 수 없다. | G9: "1장에서 고른 비교기업이 지금도 적절한가"를 매 장마다 다시 묻는다[Ch03 슬라이드 18]. 규모가 크게 다르면 peer를 좁히거나 중위값을 쓴다[Ch05 슬라이드].
C10: 1-3 주가추이(월별) | D10: 60개월 월말 종가·KOSPI로 수익률과 지수를 만든다. | E10: 7장 베타 추정: 대상 기업과 시장지수의 월별/일별 주식 수익률을 이용하여 β를 구한다[Ch07 슬라이드 10] → CAPM 자기자본비용[Ch07 슬라이드 9] → 11장 RIM·DDM의 할인율[Ch11 슬라이드 5] | F10: 할인율 r의 원천. 미래에셋 보고서의 12M 베타 1.60은 이 방식으로 구한 값이다. | G10: 월별 60개월·KOSPI 기준으로 통일하고 R²를 확인한다. 실무에서는 베타가 장기적으로 1로 회귀한다는 실증에 근거하여 조정베타(0.67×β+0.33)를 쓰기도 한다- 블룸버그 조정베타 [Ch07 슬라이드 10].
C11: 1-4 보고서비교 1-5·1-6 첨부 | D11: 애널리스트 보고서와 신용평가 보고서를 대조한다. | E11: 7장 "재무제표로 보는 위험 — 관점이 다르다": 주가 변동성(주주) vs 파산 가능성(채권자)[Ch07 슬라이드 13] · 11장 가치평가 결과를 투자의견으로[Ch11 슬라이드 16] | F11: 같은 재무제표를 주주 관점(PBR·초과이익)과 채권자 관점(순차입금·이자보상)으로 읽는 연습. 2-3·2-4의 PBR 분석은 주주 관점이다. | G11: 보고서의 P/B·ROE가 후행(trailing)인지, 12개월 선행(forward, 12MF)인지, 시가총액이 유통주식수 기준인지 확인한다[Ch03 슬라이드 19].
C12: 2-1 재무상태표 | D12: 6개년 재무상태표 입력, 공통형 분석, 증감율(분석적 검토). | E12: 공통형·시계열·횡단면[Ch02 슬라이드 20~22, Ch03 슬라이드 18] · 6장 ROE 분해의 분모(평균총자산·평균자기자본)와 회전율[Ch06 슬라이드 12, 17] · 7장 부채비율·유동비율[Ch07 슬라이드 14] · 10장 추정 재무상태표는 이 시트의 항목 비중과 회전율로 만든다[Ch10 슬라이드 12~13] · 11장 RIM의 Equity₀[Ch11 슬라이드 12] | F12: 가치평가의 출발점(장부가치)이자 미래 재무상태표의 뼈대. 10장에서는 이 표를 "거꾸로" 만든다(회전율 → 자산). | G12: 계정 정의를 자료마다 확인한다(리스부채 포함 여부, 단기금융자산 범위). 자산 = 부채 + 자본 검증행은 10장 추정 재무제표에서도 그대로 쓴다[Ch10 슬라이드 14].
C13: 2-2 공통형 해석 | D13: 재무상태표에 없는 자산·부채(잠재적 자산·부채)와 구조 변화를 서술한다. | E13: 잠재적 자산·저평가 자산[Ch02 슬라이드 13~15] · 잠재적 부채와 은닉 유인[Ch02 슬라이드 17~18] · 8장 보수주의와 이익적립금(R&D·광고비)[Ch08 슬라이드 10~12] · 11장 RIM의 약점: "장부금액이 왜곡된 기업은 출발점이 부정확"[Ch11 슬라이드 13] | F13: 후반부(7~11장) 파일의 초과이익모형에서 장부금액을 조정할 때 넣을 금액의 근거가 된다. | G13: 실무의 M&A 실사에서 잠재적 부채와 비영업자산은 '순부채·부채성 항목'과 '비영업자산' 목록으로 반영된다. 잠재적 자산(계약·기술·브랜드)은 별도로 더하지 않고 EV 산정(배수·FCF 예측)에 반영하며, 거래 후 식별가능한 무형자산으로 배분된다.
C14: 2-3 PBR 비교 | D14: 결산일 종가·유통주식수·지배기업 소유주지분으로 6개년 PBR과 ROE. | E14: PBR의 정의와 1보다 큰 이유[Ch02 슬라이드 23] · 저PBR 초과수익과 그 해석(위험 vs 과잉반응)[Ch02 슬라이드 24] · PBR = PER × ROE[Ch03 슬라이드 19] · ROE 정의(평균자기자본)[Ch06 슬라이드 11] · 코리아 디스카운트와 낮은 ROE[Ch06 슬라이드 20] · 11장 주당 자기자본 → RIM·PBR[Ch11 슬라이드 5] | F14: PBR은 2장 전체의 내용을 반영하는 숫자: "분자는 시장이 본 가치, 분모는 회계가 적은 가치"[Ch02 슬라이드 23]. | G14: 분자(시가총액)와 분모(장부가치)의 귀속 주체를 맞춘다: 지배지분 ↔ 유통주식수(자기주식 제외). 12월 말과 익년 3월 말 두 시점으로 계산해 공시 전후를 비교한다[Ch02 슬라이드 23 노트].

Sheet 2-1_재무상태표
B1: [과제 ①] 재무상태표 입력 및 공통형(common-size) 분석
B2: 단위: 백만원 · 연결재무제표 기준 · 대상기업을 앞에, 비교기업을 뒤에 입력합니다. 공통형 분석은 데이터의 오른쪽에 작성합니다.
D4: 대상기업 (금액, 백만원) | K4: 비교기업 (금액, 백만원) | R4: 공통형 분석 — 대상기업 (자산총계 = 100%) | Y4: 공통형 분석 — 비교기업 (자산총계 = 100%) | AF4: 분석적 검토 — 대상기업 (전기 대비 증감율) | AL4: 분석적 검토 — 비교기업 (전기 대비 증감율) | AR4: 공통형 분석 열은 전 행에 수식이 채워져 있습니다(자산총계 = 100%).
C5: 계정과목 | D5: 2020 | E5: 2021 | F5: 2022 | G5: 2023 | H5: 2024 | I5: 2025 | K5: 2020 | L5: 2021 | M5: 2022 | N5: 2023 | O5: 2024 | P5: 2025 | R5: 2020 | S5: 2021 | T5: 2022 | U5: 2023 | V5: 2024 | W5: 2025 | Y5: 2020 | Z5: 2021 | AA5: 2022 | AB5: 2023 | AC5: 2024 | AD5: 2025 | AF5: 2020→2021 | AG5: 2021→2022 | AH5: 2022→2023 | AI5: 2023→2024 | AJ5: 2024→2025 | AL5: 2020→2021 | AM5: 2021→2022 | AN5: 2022→2023 | AO5: 2023→2024 | AP5: 2024→2025
C6: < 유동자산 > | AR6: 자산총계 행 참조가 $로 고정되어 있으므로, 그 한 칸을 복사해 공통형 영역 전체에 붙여넣으면 됩니다.
C7: 현금및현금성자산 | R7: =IFERROR(D7/D$31,"") | S7: =IFERROR(E7/E$31,"") | T7: =IFERROR(F7/F$31,"") | U7: =IFERROR(G7/G$31,"") | V7: =IFERROR(H7/H$31,"") | W7: =IFERROR(I7/I$31,"") | Y7: =IFERROR(K7/K$31,"") | Z7: =IFERROR(L7/L$31,"") | AA7: =IFERROR(M7/M$31,"") | AB7: =IFERROR(N7/N$31,"") | AC7: =IFERROR(O7/O$31,"") | AD7: =IFERROR(P7/P$31,"") | AF7: =IF(OR(D7="",D7=0),"",IFERROR(E7/D7-1,"")) | AG7: =IF(OR(E7="",E7=0),"",IFERROR(F7/E7-1,"")) | AH7: =IF(OR(F7="",F7=0),"",IFERROR(G7/F7-1,"")) | AI7: =IF(OR(G7="",G7=0),"",IFERROR(H7/G7-1,"")) | AJ7: =IF(OR(H7="",H7=0),"",IFERROR(I7/H7-1,"")) | AL7: =IF(OR(K7="",K7=0),"",IFERROR(L7/K7-1,"")) | AM7: =IF(OR(L7="",L7=0),"",IFERROR(M7/L7-1,"")) | AN7: =IF(OR(M7="",M7=0),"",IFERROR(N7/M7-1,"")) | AO7: =IF(OR(N7="",N7=0),"",IFERROR(O7/N7-1,"")) | AP7: =IF(OR(O7="",O7=0),"",IFERROR(P7/O7-1,""))
C8: 단기금융상품 | R8: =IFERROR(D8/D$31,"") | S8: =IFERROR(E8/E$31,"") | T8: =IFERROR(F8/F$31,"") | U8: =IFERROR(G8/G$31,"") | V8: =IFERROR(H8/H$31,"") | W8: =IFERROR(I8/I$31,"") | Y8: =IFERROR(K8/K$31,"") | Z8: =IFERROR(L8/L$31,"") | AA8: =IFERROR(M8/M$31,"") | AB8: =IFERROR(N8/N$31,"") | AC8: =IFERROR(O8/O$31,"") | AD8: =IFERROR(P8/P$31,"") | AF8: =IF(OR(D8="",D8=0),"",IFERROR(E8/D8-1,"")) | AG8: =IF(OR(E8="",E8=0),"",IFERROR(F8/E8-1,"")) | AH8: =IF(OR(F8="",F8=0),"",IFERROR(G8/F8-1,"")) | AI8: =IF(OR(G8="",G8=0),"",IFERROR(H8/G8-1,"")) | AJ8: =IF(OR(H8="",H8=0),"",IFERROR(I8/H8-1,"")) | AL8: =IF(OR(K8="",K8=0),"",IFERROR(L8/K8-1,"")) | AM8: =IF(OR(L8="",L8=0),"",IFERROR(M8/L8-1,"")) | AN8: =IF(OR(M8="",M8=0),"",IFERROR(N8/M8-1,"")) | AO8: =IF(OR(N8="",N8=0),"",IFERROR(O8/N8-1,"")) | AP8: =IF(OR(O8="",O8=0),"",IFERROR(P8/O8-1,"")) | AR8: 공통형 분석의 분모는 언제나 '자산총계'입니다. 부채·자본 항목도 자본총계가 아니라 자산총계로 나눕니다.
C9: 유동 당기손익인식금융자산 | R9: =IFERROR(D9/D$31,"") | S9: =IFERROR(E9/E$31,"") | T9: =IFERROR(F9/F$31,"") | U9: =IFERROR(G9/G$31,"") | V9: =IFERROR(H9/H$31,"") | W9: =IFERROR(I9/I$31,"") | Y9: =IFERROR(K9/K$31,"") | Z9: =IFERROR(L9/L$31,"") | AA9: =IFERROR(M9/M$31,"") | AB9: =IFERROR(N9/N$31,"") | AC9: =IFERROR(O9/O$31,"") | AD9: =IFERROR(P9/P$31,"") | AF9: =IF(OR(D9="",D9=0),"",IFERROR(E9/D9-1,"")) | AG9: =IF(OR(E9="",E9=0),"",IFERROR(F9/E9-1,"")) | AH9: =IF(OR(F9="",F9=0),"",IFERROR(G9/F9-1,"")) | AI9: =IF(OR(G9="",G9=0),"",IFERROR(H9/G9-1,"")) | AJ9: =IF(OR(H9="",H9=0),"",IFERROR(I9/H9-1,"")) | AL9: =IF(OR(K9="",K9=0),"",IFERROR(L9/K9-1,"")) | AM9: =IF(OR(L9="",L9=0),"",IFERROR(M9/L9-1,"")) | AN9: =IF(OR(M9="",M9=0),"",IFERROR(N9/M9-1,"")) | AO9: =IF(OR(N9="",N9=0),"",IFERROR(O9/N9-1,"")) | AP9: =IF(OR(O9="",O9=0),"",IFERROR(P9/O9-1,""))
C10: 유동 기타포괄손익인식금융자산 | R10: =IFERROR(D10/D$31,"") | S10: =IFERROR(E10/E$31,"") | T10: =IFERROR(F10/F$31,"") | U10: =IFERROR(G10/G$31,"") | V10: =IFERROR(H10/H$31,"") | W10: =IFERROR(I10/I$31,"") | Y10: =IFERROR(K10/K$31,"") | Z10: =IFERROR(L10/L$31,"") | AA10: =IFERROR(M10/M$31,"") | AB10: =IFERROR(N10/N$31,"") | AC10: =IFERROR(O10/O$31,"") | AD10: =IFERROR(P10/P$31,"") | AF10: =IF(OR(D10="",D10=0),"",IFERROR(E10/D10-1,"")) | AG10: =IF(OR(E10="",E10=0),"",IFERROR(F10/E10-1,"")) | AH10: =IF(OR(F10="",F10=0),"",IFERROR(G10/F10-1,"")) | AI10: =IF(OR(G10="",G10=0),"",IFERROR(H10/G10-1,"")) | AJ10: =IF(OR(H10="",H10=0),"",IFERROR(I10/H10-1,"")) | AL10: =IF(OR(K10="",K10=0),"",IFERROR(L10/K10-1,"")) | AM10: =IF(OR(L10="",L10=0),"",IFERROR(M10/L10-1,"")) | AN10: =IF(OR(M10="",M10=0),"",IFERROR(N10/M10-1,"")) | AO10: =IF(OR(N10="",N10=0),"",IFERROR(O10/N10-1,"")) | AP10: =IF(OR(O10="",O10=0),"",IFERROR(P10/O10-1,"")) | AR10: 입력 칸(노란색)은 6개년 모두 채워야 합니다. 해당 항목이 없는 회사면 0을 입력하세요. 빈칸이면 소계가 어긋납니다.
C11: 매출채권 및 기타유동채권 | R11: =IFERROR(D11/D$31,"") | S11: =IFERROR(E11/E$31,"") | T11: =IFERROR(F11/F$31,"") | U11: =IFERROR(G11/G$31,"") | V11: =IFERROR(H11/H$31,"") | W11: =IFERROR(I11/I$31,"") | Y11: =IFERROR(K11/K$31,"") | Z11: =IFERROR(L11/L$31,"") | AA11: =IFERROR(M11/M$31,"") | AB11: =IFERROR(N11/N$31,"") | AC11: =IFERROR(O11/O$31,"") | AD11: =IFERROR(P11/P$31,"") | AF11: =IF(OR(D11="",D11=0),"",IFERROR(E11/D11-1,"")) | AG11: =IF(OR(E11="",E11=0),"",IFERROR(F11/E11-1,"")) | AH11: =IF(OR(F11="",F11=0),"",IFERROR(G11/F11-1,"")) | AI11: =IF(OR(G11="",G11=0),"",IFERROR(H11/G11-1,"")) | AJ11: =IF(OR(H11="",H11=0),"",IFERROR(I11/H11-1,"")) | AL11: =IF(OR(K11="",K11=0),"",IFERROR(L11/K11-1,"")) | AM11: =IF(OR(L11="",L11=0),"",IFERROR(M11/L11-1,"")) | AN11: =IF(OR(M11="",M11=0),"",IFERROR(N11/M11-1,"")) | AO11: =IF(OR(N11="",N11=0),"",IFERROR(O11/N11-1,"")) | AP11: =IF(OR(O11="",O11=0),"",IFERROR(P11/O11-1,""))
C12: 재고자산 | R12: =IFERROR(D12/D$31,"") | S12: =IFERROR(E12/E$31,"") | T12: =IFERROR(F12/F$31,"") | U12: =IFERROR(G12/G$31,"") | V12: =IFERROR(H12/H$31,"") | W12: =IFERROR(I12/I$31,"") | Y12: =IFERROR(K12/K$31,"") | Z12: =IFERROR(L12/L$31,"") | AA12: =IFERROR(M12/M$31,"") | AB12: =IFERROR(N12/N$31,"") | AC12: =IFERROR(O12/O$31,"") | AD12: =IFERROR(P12/P$31,"") | AF12: =IF(OR(D12="",D12=0),"",IFERROR(E12/D12-1,"")) | AG12: =IF(OR(E12="",E12=0),"",IFERROR(F12/E12-1,"")) | AH12: =IF(OR(F12="",F12=0),"",IFERROR(G12/F12-1,"")) | AI12: =IF(OR(G12="",G12=0),"",IFERROR(H12/G12-1,"")) | AJ12: =IF(OR(H12="",H12=0),"",IFERROR(I12/H12-1,"")) | AL12: =IF(OR(K12="",K12=0),"",IFERROR(L12/K12-1,"")) | AM12: =IF(OR(L12="",L12=0),"",IFERROR(M12/L12-1,"")) | AN12: =IF(OR(M12="",M12=0),"",IFERROR(N12/M12-1,"")) | AO12: =IF(OR(N12="",N12=0),"",IFERROR(O12/N12-1,"")) | AP12: =IF(OR(O12="",O12=0),"",IFERROR(P12/O12-1,"")) | AR12: 분석적 검토는 전기 대비 증감율입니다. 매출·사업 규모의 변화에 견주어 특정 계정만 튀는지 확인하세요.
C13: 유동 파생상품 금융자산 | R13: =IFERROR(D13/D$31,"") | S13: =IFERROR(E13/E$31,"") | T13: =IFERROR(F13/F$31,"") | U13: =IFERROR(G13/G$31,"") | V13: =IFERROR(H13/H$31,"") | W13: =IFERROR(I13/I$31,"") | Y13: =IFERROR(K13/K$31,"") | Z13: =IFERROR(L13/L$31,"") | AA13: =IFERROR(M13/M$31,"") | AB13: =IFERROR(N13/N$31,"") | AC13: =IFERROR(O13/O$31,"") | AD13: =IFERROR(P13/P$31,"") | AF13: =IF(OR(D13="",D13=0),"",IFERROR(E13/D13-1,"")) | AG13: =IF(OR(E13="",E13=0),"",IFERROR(F13/E13-1,"")) | AH13: =IF(OR(F13="",F13=0),"",IFERROR(G13/F13-1,"")) | AI13: =IF(OR(G13="",G13=0),"",IFERROR(H13/G13-1,"")) | AJ13: =IF(OR(H13="",H13=0),"",IFERROR(I13/H13-1,"")) | AL13: =IF(OR(K13="",K13=0),"",IFERROR(L13/K13-1,"")) | AM13: =IF(OR(L13="",L13=0),"",IFERROR(M13/L13-1,"")) | AN13: =IF(OR(M13="",M13=0),"",IFERROR(N13/M13-1,"")) | AO13: =IF(OR(N13="",N13=0),"",IFERROR(O13/N13-1,"")) | AP13: =IF(OR(O13="",O13=0),"",IFERROR(P13/O13-1,""))
C14: 기타유동자산 | R14: =IFERROR(D14/D$31,"") | S14: =IFERROR(E14/E$31,"") | T14: =IFERROR(F14/F$31,"") | U14: =IFERROR(G14/G$31,"") | V14: =IFERROR(H14/H$31,"") | W14: =IFERROR(I14/I$31,"") | Y14: =IFERROR(K14/K$31,"") | Z14: =IFERROR(L14/L$31,"") | AA14: =IFERROR(M14/M$31,"") | AB14: =IFERROR(N14/N$31,"") | AC14: =IFERROR(O14/O$31,"") | AD14: =IFERROR(P14/P$31,"") | AF14: =IF(OR(D14="",D14=0),"",IFERROR(E14/D14-1,"")) | AG14: =IF(OR(E14="",E14=0),"",IFERROR(F14/E14-1,"")) | AH14: =IF(OR(F14="",F14=0),"",IFERROR(G14/F14-1,"")) | AI14: =IF(OR(G14="",G14=0),"",IFERROR(H14/G14-1,"")) | AJ14: =IF(OR(H14="",H14=0),"",IFERROR(I14/H14-1,"")) | AL14: =IF(OR(K14="",K14=0),"",IFERROR(L14/K14-1,"")) | AM14: =IF(OR(L14="",L14=0),"",IFERROR(M14/L14-1,"")) | AN14: =IF(OR(M14="",M14=0),"",IFERROR(N14/M14-1,"")) | AO14: =IF(OR(N14="",N14=0),"",IFERROR(O14/N14-1,"")) | AP14: =IF(OR(O14="",O14=0),"",IFERROR(P14/O14-1,""))
C15: 당기법인세자산 | R15: =IFERROR(D15/D$31,"") | S15: =IFERROR(E15/E$31,"") | T15: =IFERROR(F15/F$31,"") | U15: =IFERROR(G15/G$31,"") | V15: =IFERROR(H15/H$31,"") | W15: =IFERROR(I15/I$31,"") | Y15: =IFERROR(K15/K$31,"") | Z15: =IFERROR(L15/L$31,"") | AA15: =IFERROR(M15/M$31,"") | AB15: =IFERROR(N15/N$31,"") | AC15: =IFERROR(O15/O$31,"") | AD15: =IFERROR(P15/P$31,"") | AF15: =IF(OR(D15="",D15=0),"",IFERROR(E15/D15-1,"")) | AG15: =IF(OR(E15="",E15=0),"",IFERROR(F15/E15-1,"")) | AH15: =IF(OR(F15="",F15=0),"",IFERROR(G15/F15-1,"")) | AI15: =IF(OR(G15="",G15=0),"",IFERROR(H15/G15-1,"")) | AJ15: =IF(OR(H15="",H15=0),"",IFERROR(I15/H15-1,"")) | AL15: =IF(OR(K15="",K15=0),"",IFERROR(L15/K15-1,"")) | AM15: =IF(OR(L15="",L15=0),"",IFERROR(M15/L15-1,"")) | AN15: =IF(OR(M15="",M15=0),"",IFERROR(N15/M15-1,"")) | AO15: =IF(OR(N15="",N15=0),"",IFERROR(O15/N15-1,"")) | AP15: =IF(OR(O15="",O15=0),"",IFERROR(P15/O15-1,""))
C16: 유동자산 계 | D16: =SUM(D7:D15) -> 0 | E16: =SUM(E7:E15) -> 0 | F16: =SUM(F7:F15) -> 0 | G16: =SUM(G7:G15) -> 0 | H16: =SUM(H7:H15) -> 0 | I16: =SUM(I7:I15) -> 0 | K16: =SUM(K7:K15) -> 0 | L16: =SUM(L7:L15) -> 0 | M16: =SUM(M7:M15) -> 0 | N16: =SUM(N7:N15) -> 0 | O16: =SUM(O7:O15) -> 0 | P16: =SUM(P7:P15) -> 0 | AR16: 대상기업과 비교기업이 같은 방향으로 움직였다면 산업·시장 요인, 대상기업만 움직였다면 기업 고유 요인일 가능성이 큽니다.
C17: < 비유동자산 >
C18: 장기금융상품 | R18: =IFERROR(D18/D$31,"") | S18: =IFERROR(E18/E$31,"") | T18: =IFERROR(F18/F$31,"") | U18: =IFERROR(G18/G$31,"") | V18: =IFERROR(H18/H$31,"") | W18: =IFERROR(I18/I$31,"") | Y18: =IFERROR(K18/K$31,"") | Z18: =IFERROR(L18/L$31,"") | AA18: =IFERROR(M18/M$31,"") | AB18: =IFERROR(N18/N$31,"") | AC18: =IFERROR(O18/O$31,"") | AD18: =IFERROR(P18/P$31,"") | AF18: =IF(OR(D18="",D18=0),"",IFERROR(E18/D18-1,"")) | AG18: =IF(OR(E18="",E18=0),"",IFERROR(F18/E18-1,"")) | AH18: =IF(OR(F18="",F18=0),"",IFERROR(G18/F18-1,"")) | AI18: =IF(OR(G18="",G18=0),"",IFERROR(H18/G18-1,"")) | AJ18: =IF(OR(H18="",H18=0),"",IFERROR(I18/H18-1,"")) | AL18: =IF(OR(K18="",K18=0),"",IFERROR(L18/K18-1,"")) | AM18: =IF(OR(L18="",L18=0),"",IFERROR(M18/L18-1,"")) | AN18: =IF(OR(M18="",M18=0),"",IFERROR(N18/M18-1,"")) | AO18: =IF(OR(N18="",N18=0),"",IFERROR(O18/N18-1,"")) | AP18: =IF(OR(O18="",O18=0),"",IFERROR(P18/O18-1,"")) | AR18: 전기 값이 0이거나 비어 있으면 증감율을 계산하지 않고 공란으로 둡니다. 기타자본항목처럼 전기 값이 음수인 계정은 부호가 직관과 반대로 나오니 주의하세요.
C19: 비유동 당기손익인식금융자산 | R19: =IFERROR(D19/D$31,"") | S19: =IFERROR(E19/E$31,"") | T19: =IFERROR(F19/F$31,"") | U19: =IFERROR(G19/G$31,"") | V19: =IFERROR(H19/H$31,"") | W19: =IFERROR(I19/I$31,"") | Y19: =IFERROR(K19/K$31,"") | Z19: =IFERROR(L19/L$31,"") | AA19: =IFERROR(M19/M$31,"") | AB19: =IFERROR(N19/N$31,"") | AC19: =IFERROR(O19/O$31,"") | AD19: =IFERROR(P19/P$31,"") | AF19: =IF(OR(D19="",D19=0),"",IFERROR(E19/D19-1,"")) | AG19: =IF(OR(E19="",E19=0),"",IFERROR(F19/E19-1,"")) | AH19: =IF(OR(F19="",F19=0),"",IFERROR(G19/F19-1,"")) | AI19: =IF(OR(G19="",G19=0),"",IFERROR(H19/G19-1,"")) | AJ19: =IF(OR(H19="",H19=0),"",IFERROR(I19/H19-1,"")) | AL19: =IF(OR(K19="",K19=0),"",IFERROR(L19/K19-1,"")) | AM19: =IF(OR(L19="",L19=0),"",IFERROR(M19/L19-1,"")) | AN19: =IF(OR(M19="",M19=0),"",IFERROR(N19/M19-1,"")) | AO19: =IF(OR(N19="",N19=0),"",IFERROR(O19/N19-1,"")) | AP19: =IF(OR(O19="",O19=0),"",IFERROR(P19/O19-1,""))
C20: 비유동 기타포괄손익인식금융자산 | R20: =IFERROR(D20/D$31,"") | S20: =IFERROR(E20/E$31,"") | T20: =IFERROR(F20/F$31,"") | U20: =IFERROR(G20/G$31,"") | V20: =IFERROR(H20/H$31,"") | W20: =IFERROR(I20/I$31,"") | Y20: =IFERROR(K20/K$31,"") | Z20: =IFERROR(L20/L$31,"") | AA20: =IFERROR(M20/M$31,"") | AB20: =IFERROR(N20/N$31,"") | AC20: =IFERROR(O20/O$31,"") | AD20: =IFERROR(P20/P$31,"") | AF20: =IF(OR(D20="",D20=0),"",IFERROR(E20/D20-1,"")) | AG20: =IF(OR(E20="",E20=0),"",IFERROR(F20/E20-1,"")) | AH20: =IF(OR(F20="",F20=0),"",IFERROR(G20/F20-1,"")) | AI20: =IF(OR(G20="",G20=0),"",IFERROR(H20/G20-1,"")) | AJ20: =IF(OR(H20="",H20=0),"",IFERROR(I20/H20-1,"")) | AL20: =IF(OR(K20="",K20=0),"",IFERROR(L20/K20-1,"")) | AM20: =IF(OR(L20="",L20=0),"",IFERROR(M20/L20-1,"")) | AN20: =IF(OR(M20="",M20=0),"",IFERROR(N20/M20-1,"")) | AO20: =IF(OR(N20="",N20=0),"",IFERROR(O20/N20-1,"")) | AP20: =IF(OR(O20="",O20=0),"",IFERROR(P20/O20-1,""))
C21: 관계기업및공동기업투자 | R21: =IFERROR(D21/D$31,"") | S21: =IFERROR(E21/E$31,"") | T21: =IFERROR(F21/F$31,"") | U21: =IFERROR(G21/G$31,"") | V21: =IFERROR(H21/H$31,"") | W21: =IFERROR(I21/I$31,"") | Y21: =IFERROR(K21/K$31,"") | Z21: =IFERROR(L21/L$31,"") | AA21: =IFERROR(M21/M$31,"") | AB21: =IFERROR(N21/N$31,"") | AC21: =IFERROR(O21/O$31,"") | AD21: =IFERROR(P21/P$31,"") | AF21: =IF(OR(D21="",D21=0),"",IFERROR(E21/D21-1,"")) | AG21: =IF(OR(E21="",E21=0),"",IFERROR(F21/E21-1,"")) | AH21: =IF(OR(F21="",F21=0),"",IFERROR(G21/F21-1,"")) | AI21: =IF(OR(G21="",G21=0),"",IFERROR(H21/G21-1,"")) | AJ21: =IF(OR(H21="",H21=0),"",IFERROR(I21/H21-1,"")) | AL21: =IF(OR(K21="",K21=0),"",IFERROR(L21/K21-1,"")) | AM21: =IF(OR(L21="",L21=0),"",IFERROR(M21/L21-1,"")) | AN21: =IF(OR(M21="",M21=0),"",IFERROR(N21/M21-1,"")) | AO21: =IF(OR(N21="",N21=0),"",IFERROR(O21/N21-1,"")) | AP21: =IF(OR(O21="",O21=0),"",IFERROR(P21/O21-1,""))
C22: 기타비유동금융자산 | R22: =IFERROR(D22/D$31,"") | S22: =IFERROR(E22/E$31,"") | T22: =IFERROR(F22/F$31,"") | U22: =IFERROR(G22/G$31,"") | V22: =IFERROR(H22/H$31,"") | W22: =IFERROR(I22/I$31,"") | Y22: =IFERROR(K22/K$31,"") | Z22: =IFERROR(L22/L$31,"") | AA22: =IFERROR(M22/M$31,"") | AB22: =IFERROR(N22/N$31,"") | AC22: =IFERROR(O22/O$31,"") | AD22: =IFERROR(P22/P$31,"") | AF22: =IF(OR(D22="",D22=0),"",IFERROR(E22/D22-1,"")) | AG22: =IF(OR(E22="",E22=0),"",IFERROR(F22/E22-1,"")) | AH22: =IF(OR(F22="",F22=0),"",IFERROR(G22/F22-1,"")) | AI22: =IF(OR(G22="",G22=0),"",IFERROR(H22/G22-1,"")) | AJ22: =IF(OR(H22="",H22=0),"",IFERROR(I22/H22-1,"")) | AL22: =IF(OR(K22="",K22=0),"",IFERROR(L22/K22-1,"")) | AM22: =IF(OR(L22="",L22=0),"",IFERROR(M22/L22-1,"")) | AN22: =IF(OR(M22="",M22=0),"",IFERROR(N22/M22-1,"")) | AO22: =IF(OR(N22="",N22=0),"",IFERROR(O22/N22-1,"")) | AP22: =IF(OR(O22="",O22=0),"",IFERROR(P22/O22-1,""))
C23: 유형자산 | R23: =IFERROR(D23/D$31,"") | S23: =IFERROR(E23/E$31,"") | T23: =IFERROR(F23/F$31,"") | U23: =IFERROR(G23/G$31,"") | V23: =IFERROR(H23/H$31,"") | W23: =IFERROR(I23/I$31,"") | Y23: =IFERROR(K23/K$31,"") | Z23: =IFERROR(L23/L$31,"") | AA23: =IFERROR(M23/M$31,"") | AB23: =IFERROR(N23/N$31,"") | AC23: =IFERROR(O23/O$31,"") | AD23: =IFERROR(P23/P$31,"") | AF23: =IF(OR(D23="",D23=0),"",IFERROR(E23/D23-1,"")) | AG23: =IF(OR(E23="",E23=0),"",IFERROR(F23/E23-1,"")) | AH23: =IF(OR(F23="",F23=0),"",IFERROR(G23/F23-1,"")) | AI23: =IF(OR(G23="",G23=0),"",IFERROR(H23/G23-1,"")) | AJ23: =IF(OR(H23="",H23=0),"",IFERROR(I23/H23-1,"")) | AL23: =IF(OR(K23="",K23=0),"",IFERROR(L23/K23-1,"")) | AM23: =IF(OR(L23="",L23=0),"",IFERROR(M23/L23-1,"")) | AN23: =IF(OR(M23="",M23=0),"",IFERROR(N23/M23-1,"")) | AO23: =IF(OR(N23="",N23=0),"",IFERROR(O23/N23-1,"")) | AP23: =IF(OR(O23="",O23=0),"",IFERROR(P23/O23-1,""))
C24: 무형자산 | R24: =IFERROR(D24/D$31,"") | S24: =IFERROR(E24/E$31,"") | T24: =IFERROR(F24/F$31,"") | U24: =IFERROR(G24/G$31,"") | V24: =IFERROR(H24/H$31,"") | W24: =IFERROR(I24/I$31,"") | Y24: =IFERROR(K24/K$31,"") | Z24: =IFERROR(L24/L$31,"") | AA24: =IFERROR(M24/M$31,"") | AB24: =IFERROR(N24/N$31,"") | AC24: =IFERROR(O24/O$31,"") | AD24: =IFERROR(P24/P$31,"") | AF24: =IF(OR(D24="",D24=0),"",IFERROR(E24/D24-1,"")) | AG24: =IF(OR(E24="",E24=0),"",IFERROR(F24/E24-1,"")) | AH24: =IF(OR(F24="",F24=0),"",IFERROR(G24/F24-1,"")) | AI24: =IF(OR(G24="",G24=0),"",IFERROR(H24/G24-1,"")) | AJ24: =IF(OR(H24="",H24=0),"",IFERROR(I24/H24-1,"")) | AL24: =IF(OR(K24="",K24=0),"",IFERROR(L24/K24-1,"")) | AM24: =IF(OR(L24="",L24=0),"",IFERROR(M24/L24-1,"")) | AN24: =IF(OR(M24="",M24=0),"",IFERROR(N24/M24-1,"")) | AO24: =IF(OR(N24="",N24=0),"",IFERROR(O24/N24-1,"")) | AP24: =IF(OR(O24="",O24=0),"",IFERROR(P24/O24-1,""))
C25: 투자부동산 | R25: =IFERROR(D25/D$31,"") | S25: =IFERROR(E25/E$31,"") | T25: =IFERROR(F25/F$31,"") | U25: =IFERROR(G25/G$31,"") | V25: =IFERROR(H25/H$31,"") | W25: =IFERROR(I25/I$31,"") | Y25: =IFERROR(K25/K$31,"") | Z25: =IFERROR(L25/L$31,"") | AA25: =IFERROR(M25/M$31,"") | AB25: =IFERROR(N25/N$31,"") | AC25: =IFERROR(O25/O$31,"") | AD25: =IFERROR(P25/P$31,"") | AF25: =IF(OR(D25="",D25=0),"",IFERROR(E25/D25-1,"")) | AG25: =IF(OR(E25="",E25=0),"",IFERROR(F25/E25-1,"")) | AH25: =IF(OR(F25="",F25=0),"",IFERROR(G25/F25-1,"")) | AI25: =IF(OR(G25="",G25=0),"",IFERROR(H25/G25-1,"")) | AJ25: =IF(OR(H25="",H25=0),"",IFERROR(I25/H25-1,"")) | AL25: =IF(OR(K25="",K25=0),"",IFERROR(L25/K25-1,"")) | AM25: =IF(OR(L25="",L25=0),"",IFERROR(M25/L25-1,"")) | AN25: =IF(OR(M25="",M25=0),"",IFERROR(N25/M25-1,"")) | AO25: =IF(OR(N25="",N25=0),"",IFERROR(O25/N25-1,"")) | AP25: =IF(OR(O25="",O25=0),"",IFERROR(P25/O25-1,""))
C26: 비유동파생상품자산 | R26: =IFERROR(D26/D$31,"") | S26: =IFERROR(E26/E$31,"") | T26: =IFERROR(F26/F$31,"") | U26: =IFERROR(G26/G$31,"") | V26: =IFERROR(H26/H$31,"") | W26: =IFERROR(I26/I$31,"") | Y26: =IFERROR(K26/K$31,"") | Z26: =IFERROR(L26/L$31,"") | AA26: =IFERROR(M26/M$31,"") | AB26: =IFERROR(N26/N$31,"") | AC26: =IFERROR(O26/O$31,"") | AD26: =IFERROR(P26/P$31,"") | AF26: =IF(OR(D26="",D26=0),"",IFERROR(E26/D26-1,"")) | AG26: =IF(OR(E26="",E26=0),"",IFERROR(F26/E26-1,"")) | AH26: =IF(OR(F26="",F26=0),"",IFERROR(G26/F26-1,"")) | AI26: =IF(OR(G26="",G26=0),"",IFERROR(H26/G26-1,"")) | AJ26: =IF(OR(H26="",H26=0),"",IFERROR(I26/H26-1,"")) | AL26: =IF(OR(K26="",K26=0),"",IFERROR(L26/K26-1,"")) | AM26: =IF(OR(L26="",L26=0),"",IFERROR(M26/L26-1,"")) | AN26: =IF(OR(M26="",M26=0),"",IFERROR(N26/M26-1,"")) | AO26: =IF(OR(N26="",N26=0),"",IFERROR(O26/N26-1,"")) | AP26: =IF(OR(O26="",O26=0),"",IFERROR(P26/O26-1,""))
C27: 이연법인세자산 | R27: =IFERROR(D27/D$31,"") | S27: =IFERROR(E27/E$31,"") | T27: =IFERROR(F27/F$31,"") | U27: =IFERROR(G27/G$31,"") | V27: =IFERROR(H27/H$31,"") | W27: =IFERROR(I27/I$31,"") | Y27: =IFERROR(K27/K$31,"") | Z27: =IFERROR(L27/L$31,"") | AA27: =IFERROR(M27/M$31,"") | AB27: =IFERROR(N27/N$31,"") | AC27: =IFERROR(O27/O$31,"") | AD27: =IFERROR(P27/P$31,"") | AF27: =IF(OR(D27="",D27=0),"",IFERROR(E27/D27-1,"")) | AG27: =IF(OR(E27="",E27=0),"",IFERROR(F27/E27-1,"")) | AH27: =IF(OR(F27="",F27=0),"",IFERROR(G27/F27-1,"")) | AI27: =IF(OR(G27="",G27=0),"",IFERROR(H27/G27-1,"")) | AJ27: =IF(OR(H27="",H27=0),"",IFERROR(I27/H27-1,"")) | AL27: =IF(OR(K27="",K27=0),"",IFERROR(L27/K27-1,"")) | AM27: =IF(OR(L27="",L27=0),"",IFERROR(M27/L27-1,"")) | AN27: =IF(OR(M27="",M27=0),"",IFERROR(N27/M27-1,"")) | AO27: =IF(OR(N27="",N27=0),"",IFERROR(O27/N27-1,"")) | AP27: =IF(OR(O27="",O27=0),"",IFERROR(P27/O27-1,""))
C28: 기타비유동자산 | R28: =IFERROR(D28/D$31,"") | S28: =IFERROR(E28/E$31,"") | T28: =IFERROR(F28/F$31,"") | U28: =IFERROR(G28/G$31,"") | V28: =IFERROR(H28/H$31,"") | W28: =IFERROR(I28/I$31,"") | Y28: =IFERROR(K28/K$31,"") | Z28: =IFERROR(L28/L$31,"") | AA28: =IFERROR(M28/M$31,"") | AB28: =IFERROR(N28/N$31,"") | AC28: =IFERROR(O28/O$31,"") | AD28: =IFERROR(P28/P$31,"") | AF28: =IF(OR(D28="",D28=0),"",IFERROR(E28/D28-1,"")) | AG28: =IF(OR(E28="",E28=0),"",IFERROR(F28/E28-1,"")) | AH28: =IF(OR(F28="",F28=0),"",IFERROR(G28/F28-1,"")) | AI28: =IF(OR(G28="",G28=0),"",IFERROR(H28/G28-1,"")) | AJ28: =IF(OR(H28="",H28=0),"",IFERROR(I28/H28-1,"")) | AL28: =IF(OR(K28="",K28=0),"",IFERROR(L28/K28-1,"")) | AM28: =IF(OR(L28="",L28=0),"",IFERROR(M28/L28-1,"")) | AN28: =IF(OR(M28="",M28=0),"",IFERROR(N28/M28-1,"")) | AO28: =IF(OR(N28="",N28=0),"",IFERROR(O28/N28-1,"")) | AP28: =IF(OR(O28="",O28=0),"",IFERROR(P28/O28-1,""))
C29: 비유동 순확정급여자산 | R29: =IFERROR(D29/D$31,"") | S29: =IFERROR(E29/E$31,"") | T29: =IFERROR(F29/F$31,"") | U29: =IFERROR(G29/G$31,"") | V29: =IFERROR(H29/H$31,"") | W29: =IFERROR(I29/I$31,"") | Y29: =IFERROR(K29/K$31,"") | Z29: =IFERROR(L29/L$31,"") | AA29: =IFERROR(M29/M$31,"") | AB29: =IFERROR(N29/N$31,"") | AC29: =IFERROR(O29/O$31,"") | AD29: =IFERROR(P29/P$31,"") | AF29: =IF(OR(D29="",D29=0),"",IFERROR(E29/D29-1,"")) | AG29: =IF(OR(E29="",E29=0),"",IFERROR(F29/E29-1,"")) | AH29: =IF(OR(F29="",F29=0),"",IFERROR(G29/F29-1,"")) | AI29: =IF(OR(G29="",G29=0),"",IFERROR(H29/G29-1,"")) | AJ29: =IF(OR(H29="",H29=0),"",IFERROR(I29/H29-1,"")) | AL29: =IF(OR(K29="",K29=0),"",IFERROR(L29/K29-1,"")) | AM29: =IF(OR(L29="",L29=0),"",IFERROR(M29/L29-1,"")) | AN29: =IF(OR(M29="",M29=0),"",IFERROR(N29/M29-1,"")) | AO29: =IF(OR(N29="",N29=0),"",IFERROR(O29/N29-1,"")) | AP29: =IF(OR(O29="",O29=0),"",IFERROR(P29/O29-1,""))
C30: 비유동자산 계 | D30: =SUM(D18:D29) -> 0 | E30: =SUM(E18:E29) -> 0 | F30: =SUM(F18:F29) -> 0 | G30: =SUM(G18:G29) -> 0 | H30: =SUM(H18:H29) -> 0 | I30: =SUM(I18:I29) -> 0 | K30: =SUM(K18:K29) -> 0 | L30: =SUM(L18:L29) -> 0 | M30: =SUM(M18:M29) -> 0 | N30: =SUM(N18:N29) -> 0 | O30: =SUM(O18:O29) -> 0 | P30: =SUM(P18:P29) -> 0
C31: 자산총계 | D31: =D16+D30 -> 0 | E31: =E16+E30 -> 0 | F31: =F16+F30 -> 0 | G31: =G16+G30 -> 0 | H31: =H16+H30 -> 0 | I31: =I16+I30 -> 0 | K31: =K16+K30 -> 0 | L31: =L16+L30 -> 0 | M31: =M16+M30 -> 0 | N31: =N16+N30 -> 0 | O31: =O16+O30 -> 0 | P31: =P16+P30 -> 0
C32: < 유동부채 >
C33: 매입채무 및 기타유동채무 | R33: =IFERROR(D33/D$31,"") | S33: =IFERROR(E33/E$31,"") | T33: =IFERROR(F33/F$31,"") | U33: =IFERROR(G33/G$31,"") | V33: =IFERROR(H33/H$31,"") | W33: =IFERROR(I33/I$31,"") | Y33: =IFERROR(K33/K$31,"") | Z33: =IFERROR(L33/L$31,"") | AA33: =IFERROR(M33/M$31,"") | AB33: =IFERROR(N33/N$31,"") | AC33: =IFERROR(O33/O$31,"") | AD33: =IFERROR(P33/P$31,"") | AF33: =IF(OR(D33="",D33=0),"",IFERROR(E33/D33-1,"")) | AG33: =IF(OR(E33="",E33=0),"",IFERROR(F33/E33-1,"")) | AH33: =IF(OR(F33="",F33=0),"",IFERROR(G33/F33-1,"")) | AI33: =IF(OR(G33="",G33=0),"",IFERROR(H33/G33-1,"")) | AJ33: =IF(OR(H33="",H33=0),"",IFERROR(I33/H33-1,"")) | AL33: =IF(OR(K33="",K33=0),"",IFERROR(L33/K33-1,"")) | AM33: =IF(OR(L33="",L33=0),"",IFERROR(M33/L33-1,"")) | AN33: =IF(OR(M33="",M33=0),"",IFERROR(N33/M33-1,"")) | AO33: =IF(OR(N33="",N33=0),"",IFERROR(O33/N33-1,"")) | AP33: =IF(OR(O33="",O33=0),"",IFERROR(P33/O33-1,""))
C34: 단기차입금 | R34: =IFERROR(D34/D$31,"") | S34: =IFERROR(E34/E$31,"") | T34: =IFERROR(F34/F$31,"") | U34: =IFERROR(G34/G$31,"") | V34: =IFERROR(H34/H$31,"") | W34: =IFERROR(I34/I$31,"") | Y34: =IFERROR(K34/K$31,"") | Z34: =IFERROR(L34/L$31,"") | AA34: =IFERROR(M34/M$31,"") | AB34: =IFERROR(N34/N$31,"") | AC34: =IFERROR(O34/O$31,"") | AD34: =IFERROR(P34/P$31,"") | AF34: =IF(OR(D34="",D34=0),"",IFERROR(E34/D34-1,"")) | AG34: =IF(OR(E34="",E34=0),"",IFERROR(F34/E34-1,"")) | AH34: =IF(OR(F34="",F34=0),"",IFERROR(G34/F34-1,"")) | AI34: =IF(OR(G34="",G34=0),"",IFERROR(H34/G34-1,"")) | AJ34: =IF(OR(H34="",H34=0),"",IFERROR(I34/H34-1,"")) | AL34: =IF(OR(K34="",K34=0),"",IFERROR(L34/K34-1,"")) | AM34: =IF(OR(L34="",L34=0),"",IFERROR(M34/L34-1,"")) | AN34: =IF(OR(M34="",M34=0),"",IFERROR(N34/M34-1,"")) | AO34: =IF(OR(N34="",N34=0),"",IFERROR(O34/N34-1,"")) | AP34: =IF(OR(O34="",O34=0),"",IFERROR(P34/O34-1,""))
C35: 유동성장기부채 (비유동차입금의 유동성 대체 부분) | R35: =IFERROR(D35/D$31,"") | S35: =IFERROR(E35/E$31,"") | T35: =IFERROR(F35/F$31,"") | U35: =IFERROR(G35/G$31,"") | V35: =IFERROR(H35/H$31,"") | W35: =IFERROR(I35/I$31,"") | Y35: =IFERROR(K35/K$31,"") | Z35: =IFERROR(L35/L$31,"") | AA35: =IFERROR(M35/M$31,"") | AB35: =IFERROR(N35/N$31,"") | AC35: =IFERROR(O35/O$31,"") | AD35: =IFERROR(P35/P$31,"") | AF35: =IF(OR(D35="",D35=0),"",IFERROR(E35/D35-1,"")) | AG35: =IF(OR(E35="",E35=0),"",IFERROR(F35/E35-1,"")) | AH35: =IF(OR(F35="",F35=0),"",IFERROR(G35/F35-1,"")) | AI35: =IF(OR(G35="",G35=0),"",IFERROR(H35/G35-1,"")) | AJ35: =IF(OR(H35="",H35=0),"",IFERROR(I35/H35-1,"")) | AL35: =IF(OR(K35="",K35=0),"",IFERROR(L35/K35-1,"")) | AM35: =IF(OR(L35="",L35=0),"",IFERROR(M35/L35-1,"")) | AN35: =IF(OR(M35="",M35=0),"",IFERROR(N35/M35-1,"")) | AO35: =IF(OR(N35="",N35=0),"",IFERROR(O35/N35-1,"")) | AP35: =IF(OR(O35="",O35=0),"",IFERROR(P35/O35-1,""))
C36: 유동성전환사채 | R36: =IFERROR(D36/D$31,"") | S36: =IFERROR(E36/E$31,"") | T36: =IFERROR(F36/F$31,"") | U36: =IFERROR(G36/G$31,"") | V36: =IFERROR(H36/H$31,"") | W36: =IFERROR(I36/I$31,"") | Y36: =IFERROR(K36/K$31,"") | Z36: =IFERROR(L36/L$31,"") | AA36: =IFERROR(M36/M$31,"") | AB36: =IFERROR(N36/N$31,"") | AC36: =IFERROR(O36/O$31,"") | AD36: =IFERROR(P36/P$31,"") | AF36: =IF(OR(D36="",D36=0),"",IFERROR(E36/D36-1,"")) | AG36: =IF(OR(E36="",E36=0),"",IFERROR(F36/E36-1,"")) | AH36: =IF(OR(F36="",F36=0),"",IFERROR(G36/F36-1,"")) | AI36: =IF(OR(G36="",G36=0),"",IFERROR(H36/G36-1,"")) | AJ36: =IF(OR(H36="",H36=0),"",IFERROR(I36/H36-1,"")) | AL36: =IF(OR(K36="",K36=0),"",IFERROR(L36/K36-1,"")) | AM36: =IF(OR(L36="",L36=0),"",IFERROR(M36/L36-1,"")) | AN36: =IF(OR(M36="",M36=0),"",IFERROR(N36/M36-1,"")) | AO36: =IF(OR(N36="",N36=0),"",IFERROR(O36/N36-1,"")) | AP36: =IF(OR(O36="",O36=0),"",IFERROR(P36/O36-1,""))
C37: 유동계약부채 | R37: =IFERROR(D37/D$31,"") | S37: =IFERROR(E37/E$31,"") | T37: =IFERROR(F37/F$31,"") | U37: =IFERROR(G37/G$31,"") | V37: =IFERROR(H37/H$31,"") | W37: =IFERROR(I37/I$31,"") | Y37: =IFERROR(K37/K$31,"") | Z37: =IFERROR(L37/L$31,"") | AA37: =IFERROR(M37/M$31,"") | AB37: =IFERROR(N37/N$31,"") | AC37: =IFERROR(O37/O$31,"") | AD37: =IFERROR(P37/P$31,"") | AF37: =IF(OR(D37="",D37=0),"",IFERROR(E37/D37-1,"")) | AG37: =IF(OR(E37="",E37=0),"",IFERROR(F37/E37-1,"")) | AH37: =IF(OR(F37="",F37=0),"",IFERROR(G37/F37-1,"")) | AI37: =IF(OR(G37="",G37=0),"",IFERROR(H37/G37-1,"")) | AJ37: =IF(OR(H37="",H37=0),"",IFERROR(I37/H37-1,"")) | AL37: =IF(OR(K37="",K37=0),"",IFERROR(L37/K37-1,"")) | AM37: =IF(OR(L37="",L37=0),"",IFERROR(M37/L37-1,"")) | AN37: =IF(OR(M37="",M37=0),"",IFERROR(N37/M37-1,"")) | AO37: =IF(OR(N37="",N37=0),"",IFERROR(O37/N37-1,"")) | AP37: =IF(OR(O37="",O37=0),"",IFERROR(P37/O37-1,""))
C38: 유동 파생상품 금융부채 | R38: =IFERROR(D38/D$31,"") | S38: =IFERROR(E38/E$31,"") | T38: =IFERROR(F38/F$31,"") | U38: =IFERROR(G38/G$31,"") | V38: =IFERROR(H38/H$31,"") | W38: =IFERROR(I38/I$31,"") | Y38: =IFERROR(K38/K$31,"") | Z38: =IFERROR(L38/L$31,"") | AA38: =IFERROR(M38/M$31,"") | AB38: =IFERROR(N38/N$31,"") | AC38: =IFERROR(O38/O$31,"") | AD38: =IFERROR(P38/P$31,"") | AF38: =IF(OR(D38="",D38=0),"",IFERROR(E38/D38-1,"")) | AG38: =IF(OR(E38="",E38=0),"",IFERROR(F38/E38-1,"")) | AH38: =IF(OR(F38="",F38=0),"",IFERROR(G38/F38-1,"")) | AI38: =IF(OR(G38="",G38=0),"",IFERROR(H38/G38-1,"")) | AJ38: =IF(OR(H38="",H38=0),"",IFERROR(I38/H38-1,"")) | AL38: =IF(OR(K38="",K38=0),"",IFERROR(L38/K38-1,"")) | AM38: =IF(OR(L38="",L38=0),"",IFERROR(M38/L38-1,"")) | AN38: =IF(OR(M38="",M38=0),"",IFERROR(N38/M38-1,"")) | AO38: =IF(OR(N38="",N38=0),"",IFERROR(O38/N38-1,"")) | AP38: =IF(OR(O38="",O38=0),"",IFERROR(P38/O38-1,""))
C39: 당기법인세부채 | R39: =IFERROR(D39/D$31,"") | S39: =IFERROR(E39/E$31,"") | T39: =IFERROR(F39/F$31,"") | U39: =IFERROR(G39/G$31,"") | V39: =IFERROR(H39/H$31,"") | W39: =IFERROR(I39/I$31,"") | Y39: =IFERROR(K39/K$31,"") | Z39: =IFERROR(L39/L$31,"") | AA39: =IFERROR(M39/M$31,"") | AB39: =IFERROR(N39/N$31,"") | AC39: =IFERROR(O39/O$31,"") | AD39: =IFERROR(P39/P$31,"") | AF39: =IF(OR(D39="",D39=0),"",IFERROR(E39/D39-1,"")) | AG39: =IF(OR(E39="",E39=0),"",IFERROR(F39/E39-1,"")) | AH39: =IF(OR(F39="",F39=0),"",IFERROR(G39/F39-1,"")) | AI39: =IF(OR(G39="",G39=0),"",IFERROR(H39/G39-1,"")) | AJ39: =IF(OR(H39="",H39=0),"",IFERROR(I39/H39-1,"")) | AL39: =IF(OR(K39="",K39=0),"",IFERROR(L39/K39-1,"")) | AM39: =IF(OR(L39="",L39=0),"",IFERROR(M39/L39-1,"")) | AN39: =IF(OR(M39="",M39=0),"",IFERROR(N39/M39-1,"")) | AO39: =IF(OR(N39="",N39=0),"",IFERROR(O39/N39-1,"")) | AP39: =IF(OR(O39="",O39=0),"",IFERROR(P39/O39-1,""))
C40: 유동 리스부채 | R40: =IFERROR(D40/D$31,"") | S40: =IFERROR(E40/E$31,"") | T40: =IFERROR(F40/F$31,"") | U40: =IFERROR(G40/G$31,"") | V40: =IFERROR(H40/H$31,"") | W40: =IFERROR(I40/I$31,"") | Y40: =IFERROR(K40/K$31,"") | Z40: =IFERROR(L40/L$31,"") | AA40: =IFERROR(M40/M$31,"") | AB40: =IFERROR(N40/N$31,"") | AC40: =IFERROR(O40/O$31,"") | AD40: =IFERROR(P40/P$31,"") | AF40: =IF(OR(D40="",D40=0),"",IFERROR(E40/D40-1,"")) | AG40: =IF(OR(E40="",E40=0),"",IFERROR(F40/E40-1,"")) | AH40: =IF(OR(F40="",F40=0),"",IFERROR(G40/F40-1,"")) | AI40: =IF(OR(G40="",G40=0),"",IFERROR(H40/G40-1,"")) | AJ40: =IF(OR(H40="",H40=0),"",IFERROR(I40/H40-1,"")) | AL40: =IF(OR(K40="",K40=0),"",IFERROR(L40/K40-1,"")) | AM40: =IF(OR(L40="",L40=0),"",IFERROR(M40/L40-1,"")) | AN40: =IF(OR(M40="",M40=0),"",IFERROR(N40/M40-1,"")) | AO40: =IF(OR(N40="",N40=0),"",IFERROR(O40/N40-1,"")) | AP40: =IF(OR(O40="",O40=0),"",IFERROR(P40/O40-1,""))
C41: 유동성전환상환우선주부채 | R41: =IFERROR(D41/D$31,"") | S41: =IFERROR(E41/E$31,"") | T41: =IFERROR(F41/F$31,"") | U41: =IFERROR(G41/G$31,"") | V41: =IFERROR(H41/H$31,"") | W41: =IFERROR(I41/I$31,"") | Y41: =IFERROR(K41/K$31,"") | Z41: =IFERROR(L41/L$31,"") | AA41: =IFERROR(M41/M$31,"") | AB41: =IFERROR(N41/N$31,"") | AC41: =IFERROR(O41/O$31,"") | AD41: =IFERROR(P41/P$31,"") | AF41: =IF(OR(D41="",D41=0),"",IFERROR(E41/D41-1,"")) | AG41: =IF(OR(E41="",E41=0),"",IFERROR(F41/E41-1,"")) | AH41: =IF(OR(F41="",F41=0),"",IFERROR(G41/F41-1,"")) | AI41: =IF(OR(G41="",G41=0),"",IFERROR(H41/G41-1,"")) | AJ41: =IF(OR(H41="",H41=0),"",IFERROR(I41/H41-1,"")) | AL41: =IF(OR(K41="",K41=0),"",IFERROR(L41/K41-1,"")) | AM41: =IF(OR(L41="",L41=0),"",IFERROR(M41/L41-1,"")) | AN41: =IF(OR(M41="",M41=0),"",IFERROR(N41/M41-1,"")) | AO41: =IF(OR(N41="",N41=0),"",IFERROR(O41/N41-1,"")) | AP41: =IF(OR(O41="",O41=0),"",IFERROR(P41/O41-1,""))
...

Sheet 2-2_공통형_해석
B1: [과제 ②] Chapter Report — 재무상태표 설명
B2: 2-1 시트의 공통형 분석 결과를 근거로 서술하세요. '기업이 영위하는 사업을 충분히 이해한 후' 재무상태표를 읽는 것이 순서입니다.
C4: 항목 | D4: 대상기업 | E4: 비교기업
C5: 자산 구성의 특징 | F5: 기업이 영위하는 사업을 먼저 설명하고, 그 사업이 재무상태표의 어느 항목으로 나타나는지 연결하여 서술한다.
C6: 6개년 자산구성 변화 추이 | F6: 자산 구성(유동/비유동, 유형자산 비중 등)의 특징과 연도별 변화를 공통형 분석 결과에 근거하여 설명한다.
C7: 자금조달 구조 (부채 vs 자본) | F7: 부채와 자본의 구성, 조달 방식의 특징을 설명한다.
C8: 부채의 만기 구성 | F8: 주석에서 확인한 잠재적 부채(우발부채·지급보증·운용리스 등)와 저평가된 자산이 있는지 검토한다.
C9: 비교기업과의 가장 큰 차이 | F9: 비교기업과 구성이 뚜렷하게 다른 항목을 찾아 그 이유를 설명한다.
C10: 재무상태표에 없는 자산 (잠재적 자산)
C11: 재무상태표에 없는 부채 (잠재적 부채)
C12: 급격히 변동한 계정과 그 원인 | F12: 2-1 시트의 분석적 검토에서 30% 이상 변동한 계정을 고르고, 사업보고서 주석에서 그 원인을 찾아 서술한다.
C13: 기업 고유 변동 vs 산업 공통 변동 | F13: 같은 계정을 비교기업과 대조한다. 두 기업이 함께 움직였으면 산업 요인, 대상기업만 움직였으면 기업 고유 요인으로 나누어 설명한다.

Sheet 2-3_PBR_비교
B1: [과제 ⑥] 대상기업·비교기업 PBR 추이 비교
B2: 단위: 자본 백만원 · 주가 원 · 주식수 천주 · 자본총계와 비지배지분은 2-1 시트에서 자동으로 연결됩니다. 노란 칸(주식수·주가)만 채우면 됩니다.
C4: ■ 자료 입력과 PBR 계산
D5: 대상기업 | K5: 비교기업
C6: 항목 | D6: 2020 | E6: 2021 | F6: 2022 | G6: 2023 | H6: 2024 | I6: 2025 | K6: 2020 | L6: 2021 | M6: 2022 | N6: 2023 | O6: 2024 | P6: 2025
C7: 자본총계 (2-1 시트 연결) | D7: ='2-1_재무상태표'!D63 -> 0 | E7: ='2-1_재무상태표'!E63 -> 0 | F7: ='2-1_재무상태표'!F63 -> 0 | G7: ='2-1_재무상태표'!G63 -> 0 | H7: ='2-1_재무상태표'!H63 -> 0 | I7: ='2-1_재무상태표'!I63 -> 0 | K7: ='2-1_재무상태표'!K63 -> 0 | L7: ='2-1_재무상태표'!L63 -> 0 | M7: ='2-1_재무상태표'!M63 -> 0 | N7: ='2-1_재무상태표'!N63 -> 0 | O7: ='2-1_재무상태표'!O63 -> 0 | P7: ='2-1_재무상태표'!P63 -> 0 | R7: 비지배지분을 빼는 이유: PBR의 분자인 시가총액은 지배기업 주주의 몫이므로, 분모도 지배기업 소유주지분으로 맞춰야 짝이 맞습니다.
C8: 비지배지분 (2-1 시트 연결) | D8: ='2-1_재무상태표'!D62 -> 0 | E8: ='2-1_재무상태표'!E62 -> 0 | F8: ='2-1_재무상태표'!F62 -> 0 | G8: ='2-1_재무상태표'!G62 -> 0 | H8: ='2-1_재무상태표'!H62 -> 0 | I8: ='2-1_재무상태표'!I62 -> 0 | K8: ='2-1_재무상태표'!K62 -> 0 | L8: ='2-1_재무상태표'!L62 -> 0 | M8: ='2-1_재무상태표'!M62 -> 0 | N8: ='2-1_재무상태표'!N62 -> 0 | O8: ='2-1_재무상태표'!O62 -> 0 | P8: ='2-1_재무상태표'!P62 -> 0
C9: 지배기업 소유주지분 (= 자본총계 − 비지배지분) | D9: =D7-D8 -> 0 | E9: =E7-E8 -> 0 | F9: =F7-F8 -> 0 | G9: =G7-G8 -> 0 | H9: =H7-H8 -> 0 | I9: =I7-I8 -> 0 | K9: =K7-K8 -> 0 | L9: =L7-L8 -> 0 | M9: =M7-M8 -> 0 | N9: =N7-N8 -> 0 | O9: =O7-O8 -> 0 | P9: =P7-P8 -> 0
C10: 기말 발행주식수 (천주) | R10: 발행주식수·자기주식수는 사업보고서 "주식의 총수 등" 항목, 12월 말 종가는 KRX·네이버금융 등에서 조회합니다. 출처를 맨 아래 칸에 남기세요.
C11: 기말 자기주식수 (천주)
C12: 유통주식수 (천주) (= 발행 − 자기주식) | D12: =IF(D10="","",D10-D11) | E12: =IF(E10="","",E10-E11) | F12: =IF(F10="","",F10-F11) | G12: =IF(G10="","",G10-G11) | H12: =IF(H10="","",H10-H11) | I12: =IF(I10="","",I10-I11) | K12: =IF(K10="","",K10-K11) | L12: =IF(L10="","",L10-L11) | M12: =IF(M10="","",M10-M11) | N12: =IF(N10="","",N10-N11) | O12: =IF(O10="","",O10-O11) | P12: =IF(P10="","",P10-P11)
C13: 12월 말 종가 (원)
C14: 시가총액 (백만원) (= 종가 × 유통주식수 ÷ 1,000) | D14: =IF(OR(D12="",D13=""),"",D13*D12/1000) | E14: =IF(OR(E12="",E13=""),"",E13*E12/1000) | F14: =IF(OR(F12="",F13=""),"",F13*F12/1000) | G14: =IF(OR(G12="",G13=""),"",G13*G12/1000) | H14: =IF(OR(H12="",H13=""),"",H13*H12/1000) | I14: =IF(OR(I12="",I13=""),"",I13*I12/1000) | K14: =IF(OR(K12="",K13=""),"",K13*K12/1000) | L14: =IF(OR(L12="",L13=""),"",L13*L12/1000) | M14: =IF(OR(M12="",M13=""),"",M13*M12/1000) | N14: =IF(OR(N12="",N13=""),"",N13*N12/1000) | O14: =IF(OR(O12="",O13=""),"",O13*O12/1000) | P14: =IF(OR(P12="",P13=""),"",P13*P12/1000) | R14: 참고: DataGuide 연말 시가총액(백만원)은 자기주식을 포함한 발행주식수 기준이라 이 표의 유통주식수 기준 시총보다 큽니다.
C15: 주당순자산 BPS (원) (= 지배지분 × 1,000 ÷ 유통주식수) | D15: =IF(OR(D12="",D12=0,D9=0),"",D9*1000/D12) | E15: =IF(OR(E12="",E12=0,E9=0),"",E9*1000/E12) | F15: =IF(OR(F12="",F12=0,F9=0),"",F9*1000/F12) | G15: =IF(OR(G12="",G12=0,G9=0),"",G9*1000/G12) | H15: =IF(OR(H12="",H12=0,H9=0),"",H9*1000/H12) | I15: =IF(OR(I12="",I12=0,I9=0),"",I9*1000/I12) | K15: =IF(OR(K12="",K12=0,K9=0),"",K9*1000/K12) | L15: =IF(OR(L12="",L12=0,L9=0),"",L9*1000/L12) | M15: =IF(OR(M12="",M12=0,M9=0),"",M9*1000/M12) | N15: =IF(OR(N12="",N12=0,N9=0),"",N9*1000/N12) | O15: =IF(OR(O12="",O12=0,O9=0),"",O9*1000/O12) | P15: =IF(OR(P12="",P12=0,P9=0),"",P9*1000/P12) | R15: 단위 환산: 지배지분(백만원)×1,000,000 ÷ (유통주식수(천주)×1,000) = 지배지분×1,000 ÷ 유통주식수(천주).
C16: PBR (= 종가 ÷ BPS = 시가총액 ÷ 지배지분) | D16: =IF(OR(D15="",D13=""),"",D13/D15) | E16: =IF(OR(E15="",E13=""),"",E13/E15) | F16: =IF(OR(F15="",F13=""),"",F13/F15) | G16: =IF(OR(G15="",G13=""),"",G13/G15) | H16: =IF(OR(H15="",H13=""),"",H13/H15) | I16: =IF(OR(I15="",I13=""),"",I13/I15) | K16: =IF(OR(K15="",K13=""),"",K13/K15) | L16: =IF(OR(L15="",L13=""),"",L13/L15) | M16: =IF(OR(M15="",M13=""),"",M13/M15) | N16: =IF(OR(N15="",N13=""),"",N13/N15) | O16: =IF(OR(O15="",O13=""),"",O13/O15) | P16: =IF(OR(P15="",P13=""),"",P13/P15)
C17: 자기자본이익률 ROE (= 지배주주순이익(3-1) ÷ 평균 지배기업 소유주지분, 2021~ 수식) | E17: =IF(OR('3-1_손익계산서'!E21="",E9=0,D9=0),"",'3-1_손익계산서'!E21/((E9+D9)/2)) | F17: =IF(OR('3-1_손익계산서'!F21="",F9=0,E9=0),"",'3-1_손익계산서'!F21/((F9+E9)/2)) | G17: =IF(OR('3-1_손익계산서'!G21="",G9=0,F9=0),"",'3-1_손익계산서'!G21/((G9+F9)/2)) | H17: =IF(OR('3-1_손익계산서'!H21="",H9=0,G9=0),"",'3-1_손익계산서'!H21/((H9+G9)/2)) | I17: =IF(OR('3-1_손익계산서'!I21="",I9=0,H9=0),"",'3-1_손익계산서'!I21/((I9+H9)/2)) | L17: =IF(OR('3-1_손익계산서'!L21="",L9=0,K9=0),"",'3-1_손익계산서'!L21/((L9+K9)/2)) | M17: =IF(OR('3-1_손익계산서'!M21="",M9=0,L9=0),"",'3-1_손익계산서'!M21/((M9+L9)/2)) | N17: =IF(OR('3-1_손익계산서'!N21="",N9=0,M9=0),"",'3-1_손익계산서'!N21/((N9+M9)/2)) | O17: =IF(OR('3-1_손익계산서'!O21="",O9=0,N9=0),"",'3-1_손익계산서'!O21/((O9+N9)/2)) | P17: =IF(OR('3-1_손익계산서'!P21="",P9=0,O9=0),"",'3-1_손익계산서'!P21/((P9+O9)/2)) | R17: ROE = 3-1 시트의 지배기업 소유주지분 순이익 ÷ (당기말 + 전기말 지배지분) ÷ 2. 6-1 시트의 ROE는 교재 정의(당기순이익 ÷ 평균자본총계)라 비지배지분이 있는 기업에서는 값이 약간 다릅니다.
C18: 검증: 2-1 시트 자본총계 입력 여부 | D18: =IF(D7=0,"01시트 미입력","OK") -> 01시트 미입력 | E18: =IF(E7=0,"01시트 미입력","OK") -> 01시트 미입력 | F18: =IF(F7=0,"01시트 미입력","OK") -> 01시트 미입력 | G18: =IF(G7=0,"01시트 미입력","OK") -> 01시트 미입력 | H18: =IF(H7=0,"01시트 미입력","OK") -> 01시트 미입력 | I18: =IF(I7=0,"01시트 미입력","OK") -> 01시트 미입력 | K18: =IF(K7=0,"01시트 미입력","OK") -> 01시트 미입력 | L18: =IF(L7=0,"01시트 미입력","OK") -> 01시트 미입력 | M18: =IF(M7=0,"01시트 미입력","OK") -> 01시트 미입력 | N18: =IF(N7=0,"01시트 미입력","OK") -> 01시트 미입력 | O18: =IF(O7=0,"01시트 미입력","OK") -> 01시트 미입력 | P18: =IF(P7=0,"01시트 미입력","OK") -> 01시트 미입력
D20: PBR 감소
C21: ■ PBR 추이 비교
C22: 연도 | D22: 대상기업 PBR | E22: 비교기업 PBR | F22: 차이 (대상 − 비교) | G22: 상대 PBR (대상 ÷ 비교) | H22: 대상기업 시총 − 지배지분 (백만원) | I22: 비교기업 시총 − 지배지분 (백만원)
C23: 2020 | D23: =D16 | E23: =K16 | F23: =IF(OR(D23="",E23=""),"",D23-E23) | G23: =IF(OR(D23="",E23="",E23=0),"",D23/E23) | H23: =IF(D14="","",D14-D9) | I23: =IF(K14="","",K14-K9) | K23: '시총 − 지배지분'은 시장이 재무상태표 밖에서 인정(또는 차감)하는 금액입니다.
C24: 2021 | D24: =E16 | E24: =L16 | F24: =IF(OR(D24="",E24=""),"",D24-E24) | G24: =IF(OR(D24="",E24="",E24=0),"",D24/E24) | H24: =IF(E14="","",E14-E9) | I24: =IF(L14="","",L14-L9) | K24: 양(+)이면 장부에 없는 자산·미래 초과이익을, 음(−)이면 장부에 없는 부채나 장부가치의 과대계상을 시장이 보고 있다는 뜻입니다.
C25: 2022 | D25: =F16 | E25: =M16 | F25: =IF(OR(D25="",E25=""),"",D25-E25) | G25: =IF(OR(D25="",E25="",E25=0),"",D25/E25) | H25: =IF(F14="","",F14-F9) | I25: =IF(M14="","",M14-M9) | K25: 2장에서 찾아낸 잠재적 자산·부채(2-2 시트 10·11행)로 이 금액의 몇 %가 설명되는지 후반부 파일의 초과이익모형 시트에서 확인합니다.
C26: 2023 | D26: =G16 | E26: =N16 | F26: =IF(OR(D26="",E26=""),"",D26-E26) | G26: =IF(OR(D26="",E26="",E26=0),"",D26/E26) | H26: =IF(G14="","",G14-G9) | I26: =IF(N14="","",N14-N9)
C27: 2024 | D27: =H16 | E27: =O16 | F27: =IF(OR(D27="",E27=""),"",D27-E27) | G27: =IF(OR(D27="",E27="",E27=0),"",D27/E27) | H27: =IF(H14="","",H14-H9) | I27: =IF(O14="","",O14-O9) | K27: 차트는 아래에 자동으로 그려집니다. 데이터를 입력하면 선이 나타납니다.
C28: 2025 | D28: =I16 | E28: =P16 | F28: =IF(OR(D28="",E28=""),"",D28-E28) | G28: =IF(OR(D28="",E28="",E28=0),"",D28/E28) | H28: =IF(I14="","",I14-I9) | I28: =IF(P14="","",P14-P9)
C29: 6개년 평균 | D29: =IFERROR(AVERAGE(D23:D28),"") | E29: =IFERROR(AVERAGE(E23:E28),"") | F29: =IFERROR(AVERAGE(F23:F28),"") | G29: =IFERROR(AVERAGE(G23:G28),"") | H29: =IFERROR(AVERAGE(H23:H28),"") | I29: =IFERROR(AVERAGE(I23:I28),"")
C30: 최대 | D30: =IFERROR(MAX(D23:D28),"") -> 0 | E30: =IFERROR(MAX(E23:E28),"") -> 0 | F30: =IFERROR(MAX(F23:F28),"") -> 0 | G30: =IFERROR(MAX(G23:G28),"") -> 0 | H30: =IFERROR(MAX(H23:H28),"") -> 0 | I30: =IFERROR(MAX(I23:I28),"") -> 0
C31: 최소 | D31: =IFERROR(MIN(D23:D28),"") -> 0 | E31: =IFERROR(MIN(E23:E28),"") -> 0 | F31: =IFERROR(MIN(F23:F28),"") -> 0 | G31: =IFERROR(MIN(G23:G28),"") -> 0 | H31: =IFERROR(MIN(H23:H28),"") -> 0 | I31: =IFERROR(MIN(I23:I28),"") -> 0
C48: ■ 해석 (Chapter Report에 옮겨 적을 내용)
C49: (1) 대상기업 PBR이 1보다 크(작)게 유지되는 이유를 재무상태표에 없는 자산(브랜드·기술·R&D 등)과 부채(우발부채·지급보증 등)의 관점에서 설명해 보세요.
C52: (2) 두 기업의 PBR 차이(F열)와 상대 PBR(G열)이 6년 동안 어떻게 움직였나요? 같이 움직였다면 산업(톡신·필러 수요와 수출 사이클, 규제) 요인, 따로 움직였다면 기업 고유 요인(소송·허가·지배구조)입니다.
C55: (3)PBR이 크게 변한 해를 고르고, 그 해의 2-1 시트 분석적 검토(30% 이상 변동 계정)와 연결되는 항목이 있는지 찾아보세요.
C59: 자료 출처 (주가·주식수 조회처 · 조회일자)

Sheet 3-1_손익계산서
B1: [3장 과제 ①] 손익계산서 입력과 공통형 분석 (6개년, 연결)
B2: 단위: 백만원 (EPS는 원). 사업보고서 연결포괄손익계산서에서 옮겨 적습니다. 노란 칸은 입력, 회색은 수식. 공통형은 매출액 = 100%. 법인세비용은 세전이익 − 계속영업순이익으로 역산하므로 중단영업손익이 있으면 반드시 입력하세요.
D4: 대상기업 (메디톡스) | K4: 비교기업 (휴젤) | S4: 공통형 (매출액 = 100%) | T4: 대상기업 | AA4: 비교기업
C5: 항목 (연결손익계산서) | D5: 2020 | E5: 2021 | F5: 2022 | G5: 2023 | H5: 2024 | I5: 2025 | K5: 2020 | L5: 2021 | M5: 2022 | N5: 2023 | O5: 2024 | P5: 2025 | S5: 항목 | T5: 2020 | U5: 2021 | V5: 2022 | W5: 2023 | X5: 2024 | Y5: 2025 | AA5: 2020 | AB5: 2021 | AC5: 2022 | AD5: 2023 | AE5: 2024 | AF5: 2025
C6: 매출액 | S6: 매출액 | T6: =IF(OR(D$6="",D$6=0),"",D6/D$6) | U6: =IF(OR(E$6="",E$6=0),"",E6/E$6) | V6: =IF(OR(F$6="",F$6=0),"",F6/F$6) | W6: =IF(OR(G$6="",G$6=0),"",G6/G$6) | X6: =IF(OR(H$6="",H$6=0),"",H6/H$6) | Y6: =IF(OR(I$6="",I$6=0),"",I6/I$6) | AA6: =IF(OR(K$6="",K$6=0),"",K6/K$6) | AB6: =IF(OR(L$6="",L$6=0),"",L6/L$6) | AC6: =IF(OR(M$6="",M$6=0),"",M6/M$6) | AD6: =IF(OR(N$6="",N$6=0),"",N6/N$6) | AE6: =IF(OR(O$6="",O$6=0),"",O6/O$6) | AF6: =IF(OR(P$6="",P$6=0),"",P6/P$6)
C7: 매출원가 | S7: 매출원가 | T7: =IF(OR(D$6="",D$6=0),"",D7/D$6) | U7: =IF(OR(E$6="",E$6=0),"",E7/E$6) | V7: =IF(OR(F$6="",F$6=0),"",F7/F$6) | W7: =IF(OR(G$6="",G$6=0),"",G7/G$6) | X7: =IF(OR(H$6="",H$6=0),"",H7/H$6) | Y7: =IF(OR(I$6="",I$6=0),"",I7/I$6) | AA7: =IF(OR(K$6="",K$6=0),"",K7/K$6) | AB7: =IF(OR(L$6="",L$6=0),"",L7/L$6) | AC7: =IF(OR(M$6="",M$6=0),"",M7/M$6) | AD7: =IF(OR(N$6="",N$6=0),"",N7/N$6) | AE7: =IF(OR(O$6="",O$6=0),"",O7/O$6) | AF7: =IF(OR(P$6="",P$6=0),"",P7/P$6)
C8: 매출총이익 (= 매출액 − 매출원가) | D8: =D6-D7 -> 0 | E8: =E6-E7 -> 0 | F8: =F6-F7 -> 0 | G8: =G6-G7 -> 0 | H8: =H6-H7 -> 0 | I8: =I6-I7 -> 0 | K8: =K6-K7 -> 0 | L8: =L6-L7 -> 0 | M8: =M6-M7 -> 0 | N8: =N6-N7 -> 0 | O8: =O6-O7 -> 0 | P8: =P6-P7 -> 0 | S8: 매출총이익 | T8: =IF(OR(D$6="",D$6=0),"",D8/D$6) | U8: =IF(OR(E$6="",E$6=0),"",E8/E$6) | V8: =IF(OR(F$6="",F$6=0),"",F8/F$6) | W8: =IF(OR(G$6="",G$6=0),"",G8/G$6) | X8: =IF(OR(H$6="",H$6=0),"",H8/H$6) | Y8: =IF(OR(I$6="",I$6=0),"",I8/I$6) | AA8: =IF(OR(K$6="",K$6=0),"",K8/K$6) | AB8: =IF(OR(L$6="",L$6=0),"",L8/L$6) | AC8: =IF(OR(M$6="",M$6=0),"",M8/M$6) | AD8: =IF(OR(N$6="",N$6=0),"",N8/N$6) | AE8: =IF(OR(O$6="",O$6=0),"",O8/O$6) | AF8: =IF(OR(P$6="",P$6=0),"",P8/P$6)
C9: 판매비와관리비 | S9: 판매비와관리비 | T9: =IF(OR(D$6="",D$6=0),"",D9/D$6) | U9: =IF(OR(E$6="",E$6=0),"",E9/E$6) | V9: =IF(OR(F$6="",F$6=0),"",F9/F$6) | W9: =IF(OR(G$6="",G$6=0),"",G9/G$6) | X9: =IF(OR(H$6="",H$6=0),"",H9/H$6) | Y9: =IF(OR(I$6="",I$6=0),"",I9/I$6) | AA9: =IF(OR(K$6="",K$6=0),"",K9/K$6) | AB9: =IF(OR(L$6="",L$6=0),"",L9/L$6) | AC9: =IF(OR(M$6="",M$6=0),"",M9/M$6) | AD9: =IF(OR(N$6="",N$6=0),"",N9/N$6) | AE9: =IF(OR(O$6="",O$6=0),"",O9/O$6) | AF9: =IF(OR(P$6="",P$6=0),"",P9/P$6)
C10: 영업이익 (= 매출총이익 − 판관비) | D10: =D8-D9 -> 0 | E10: =E8-E9 -> 0 | F10: =F8-F9 -> 0 | G10: =G8-G9 -> 0 | H10: =H8-H9 -> 0 | I10: =I8-I9 -> 0 | K10: =K8-K9 -> 0 | L10: =L8-L9 -> 0 | M10: =M8-M9 -> 0 | N10: =N8-N9 -> 0 | O10: =O8-O9 -> 0 | P10: =P8-P9 -> 0 | S10: 영업이익 | T10: =IF(OR(D$6="",D$6=0),"",D10/D$6) | U10: =IF(OR(E$6="",E$6=0),"",E10/E$6) | V10: =IF(OR(F$6="",F$6=0),"",F10/F$6) | W10: =IF(OR(G$6="",G$6=0),"",G10/G$6) | X10: =IF(OR(H$6="",H$6=0),"",H10/H$6) | Y10: =IF(OR(I$6="",I$6=0),"",I10/I$6) | AA10: =IF(OR(K$6="",K$6=0),"",K10/K$6) | AB10: =IF(OR(L$6="",L$6=0),"",L10/L$6) | AC10: =IF(OR(M$6="",M$6=0),"",M10/M$6) | AD10: =IF(OR(N$6="",N$6=0),"",N10/N$6) | AE10: =IF(OR(O$6="",O$6=0),"",O10/O$6) | AF10: =IF(OR(P$6="",P$6=0),"",P10/P$6)
C11: 기타수익 | T11: =IF(OR(D$6="",D$6=0),"",D11/D$6) | U11: =IF(OR(E$6="",E$6=0),"",E11/E$6) | V11: =IF(OR(F$6="",F$6=0),"",F11/F$6) | W11: =IF(OR(G$6="",G$6=0),"",G11/G$6) | X11: =IF(OR(H$6="",H$6=0),"",H11/H$6) | Y11: =IF(OR(I$6="",I$6=0),"",I11/I$6) | AA11: =IF(OR(K$6="",K$6=0),"",K11/K$6) | AB11: =IF(OR(L$6="",L$6=0),"",L11/L$6) | AC11: =IF(OR(M$6="",M$6=0),"",M11/M$6) | AD11: =IF(OR(N$6="",N$6=0),"",N11/N$6) | AE11: =IF(OR(O$6="",O$6=0),"",O11/O$6) | AF11: =IF(OR(P$6="",P$6=0),"",P11/P$6)
C12: 기타비용 | T12: =IF(OR(D$6="",D$6=0),"",D12/D$6) | U12: =IF(OR(E$6="",E$6=0),"",E12/E$6) | V12: =IF(OR(F$6="",F$6=0),"",F12/F$6) | W12: =IF(OR(G$6="",G$6=0),"",G12/G$6) | X12: =IF(OR(H$6="",H$6=0),"",H12/H$6) | Y12: =IF(OR(I$6="",I$6=0),"",I12/I$6) | AA12: =IF(OR(K$6="",K$6=0),"",K12/K$6) | AB12: =IF(OR(L$6="",L$6=0),"",L12/L$6) | AC12: =IF(OR(M$6="",M$6=0),"",M12/M$6) | AD12: =IF(OR(N$6="",N$6=0),"",N12/N$6) | AE12: =IF(OR(O$6="",O$6=0),"",O12/O$6) | AF12: =IF(OR(P$6="",P$6=0),"",P12/P$6)
C13: 금융수익 | S13: 금융수익 | T13: =IF(OR(D$6="",D$6=0),"",D13/D$6) | U13: =IF(OR(E$6="",E$6=0),"",E13/E$6) | V13: =IF(OR(F$6="",F$6=0),"",F13/F$6) | W13: =IF(OR(G$6="",G$6=0),"",G13/G$6) | X13: =IF(OR(H$6="",H$6=0),"",H13/H$6) | Y13: =IF(OR(I$6="",I$6=0),"",I13/I$6) | AA13: =IF(OR(K$6="",K$6=0),"",K13/K$6) | AB13: =IF(OR(L$6="",L$6=0),"",L13/L$6) | AC13: =IF(OR(M$6="",M$6=0),"",M13/M$6) | AD13: =IF(OR(N$6="",N$6=0),"",N13/N$6) | AE13: =IF(OR(O$6="",O$6=0),"",O13/O$6) | AF13: =IF(OR(P$6="",P$6=0),"",P13/P$6)
C14: 금융원가(금융비용) | S14: 금융비용 | T14: =IF(OR(D$6="",D$6=0),"",D14/D$6) | U14: =IF(OR(E$6="",E$6=0),"",E14/E$6) | V14: =IF(OR(F$6="",F$6=0),"",F14/F$6) | W14: =IF(OR(G$6="",G$6=0),"",G14/G$6) | X14: =IF(OR(H$6="",H$6=0),"",H14/H$6) | Y14: =IF(OR(I$6="",I$6=0),"",I14/I$6) | AA14: =IF(OR(K$6="",K$6=0),"",K14/K$6) | AB14: =IF(OR(L$6="",L$6=0),"",L14/L$6) | AC14: =IF(OR(M$6="",M$6=0),"",M14/M$6) | AD14: =IF(OR(N$6="",N$6=0),"",N14/N$6) | AE14: =IF(OR(O$6="",O$6=0),"",O14/O$6) | AF14: =IF(OR(P$6="",P$6=0),"",P14/P$6)
C15: 지분법손익 | T15: =IF(OR(D$6="",D$6=0),"",D15/D$6) | U15: =IF(OR(E$6="",E$6=0),"",E15/E$6) | V15: =IF(OR(F$6="",F$6=0),"",F15/F$6) | W15: =IF(OR(G$6="",G$6=0),"",G15/G$6) | X15: =IF(OR(H$6="",H$6=0),"",H15/H$6) | Y15: =IF(OR(I$6="",I$6=0),"",I15/I$6) | AA15: =IF(OR(K$6="",K$6=0),"",K15/K$6) | AB15: =IF(OR(L$6="",L$6=0),"",L15/L$6) | AC15: =IF(OR(M$6="",M$6=0),"",M15/M$6) | AD15: =IF(OR(N$6="",N$6=0),"",N15/N$6) | AE15: =IF(OR(O$6="",O$6=0),"",O15/O$6) | AF15: =IF(OR(P$6="",P$6=0),"",P15/P$6)
C16: 영업외손익 합계 (= 기타수익 − 기타비용 + 금융수익 − 금융원가 + 지분법손익) | D16: =IF(D17="","",N(D11)-N(D12)+N(D13)-N(D14)+N(D15)) | E16: =IF(E17="","",N(E11)-N(E12)+N(E13)-N(E14)+N(E15)) | F16: =IF(F17="","",N(F11)-N(F12)+N(F13)-N(F14)+N(F15)) | G16: =IF(G17="","",N(G11)-N(G12)+N(G13)-N(G14)+N(G15)) | H16: =IF(H17="","",N(H11)-N(H12)+N(H13)-N(H14)+N(H15)) | I16: =IF(I17="","",N(I11)-N(I12)+N(I13)-N(I14)+N(I15)) | K16: =IF(K17="","",N(K11)-N(K12)+N(K13)-N(K14)+N(K15)) | L16: =IF(L17="","",N(L11)-N(L12)+N(L13)-N(L14)+N(L15)) | M16: =IF(M17="","",N(M11)-N(M12)+N(M13)-N(M14)+N(M15)) | N16: =IF(N17="","",N(N11)-N(N12)+N(N13)-N(N14)+N(N15)) | O16: =IF(O17="","",N(O11)-N(O12)+N(O13)-N(O14)+N(O15)) | P16: =IF(P17="","",N(P11)-N(P12)+N(P13)-N(P14)+N(P15)) | S16: 기타영업외손익 순액 | T16: =IF(OR(D$6="",D$6=0),"",D16/D$6) | U16: =IF(OR(E$6="",E$6=0),"",E16/E$6) | V16: =IF(OR(F$6="",F$6=0),"",F16/F$6) | W16: =IF(OR(G$6="",G$6=0),"",G16/G$6) | X16: =IF(OR(H$6="",H$6=0),"",H16/H$6) | Y16: =IF(OR(I$6="",I$6=0),"",I16/I$6) | AA16: =IF(OR(K$6="",K$6=0),"",K16/K$6) | AB16: =IF(OR(L$6="",L$6=0),"",L16/L$6) | AC16: =IF(OR(M$6="",M$6=0),"",M16/M$6) | AD16: =IF(OR(N$6="",N$6=0),"",N16/N$6) | AE16: =IF(OR(O$6="",O$6=0),"",O16/O$6) | AF16: =IF(OR(P$6="",P$6=0),"",P16/P$6)
